2024-07-22 14:32:50,417 - __main__ - INFO - Starting the bot
2024-07-22 14:32:50,505 - __main__ - INFO - Bot is now polling for updates
2024-07-22 14:32:51,915 - httpx - INFO - HTTP Request: POST https://api.telegram.org/bot7064977852:AAGEEutTl0D6gVt-Jgz4aXJ4mxK8mLPdL_E/getMe "HTTP/1.1 200 OK"
2024-07-22 14:32:52,995 - httpx - INFO - HTTP Request: POST https://api.telegram.org/bot7064977852:AAGEEutTl0D6gVt-Jgz4aXJ4mxK8mLPdL_E/deleteWebhook "HTTP/1.1 200 OK"
2024-07-22 14:32:52,998 - telegram.ext.Application - INFO - Application started
2024-07-22 14:32:54,069 - httpx - INFO - HTTP Request: POST https://api.telegram.org/bot7064977852:AAGEEutTl0D6gVt-Jgz4aXJ4mxK8mLPdL_E/getUpdates "HTTP/1.1 200 OK"
2024-07-22 14:32:54,071 - __main__ - INFO - Received message from user 2042811943 (None): hi
2024-07-22 14:32:54,072 - __main__ - WARNING - User 2042811943 (None) sent invalid URL: hi
2024-07-22 14:32:54,545 - httpx - INFO - HTTP Request: POST https://api.telegram.org/bot7064977852:AAGEEutTl0D6gVt-Jgz4aXJ4mxK8mLPdL_E/sendMessage "HTTP/1.1 200 OK"
2024-07-22 14:33:04,330 - httpx - INFO - HTTP Request: POST https://api.telegram.org/bot7064977852:AAGEEutTl0D6gVt-Jgz4aXJ4mxK8mLPdL_E/getUpdates "HTTP/1.1 200 OK"
2024-07-22 14:33:14,588 - httpx - INFO - HTTP Request: POST https://api.telegram.org/bot7064977852:AAGEEutTl0D6gVt-Jgz4aXJ4mxK8mLPdL_E/getUpdates "HTTP/1.1 200 OK"
2024-07-22 14:33:16,588 - httpx - INFO - HTTP Request: POST https://api.telegram.org/bot7064977852:AAGEEutTl0D6gVt-Jgz4aXJ4mxK8mLPdL_E/getUpdates "HTTP/1.1 200 OK"
2024-07-22 14:33:16,589 - __main__ - INFO - Received message from user 2042811943 (None): import logging
import re
import os
from telegram import Update
from telegram.ext import Application, CommandHandler, ContextTypes, MessageHandler, filters
import yt_dlp
from dotenv import load_dotenv
import concurrent.futures
import time
import sys

# 加载.env文件中的环境变量
load_dotenv()

# 将环境变量中的token赋值给TOKEN
TOKEN = os.getenv('TELEGRAM_BOT_TOKEN')

# 设置下载目录
DOWNLOAD_DIR = 'downloads'
if not os.path.exists(DOWNLOAD_DIR):
    os.makedirs(DOWNLOAD_DIR)

# 配置日志记录
logging.basicConfig(
    level=logging.INFO,
    format="%(asctime)s - %(name)s - %(levelname)s - %(message)s",
    handlers=[
        logging.FileHandler("bot.log"),
        logging.StreamHandler(sys.stdout)
    ]
)

logger = logging.getLogger(__name__)

# 创建线程池
executor = concurrent.futures.ThreadPoolExecutor(max_workers=5)

async def start(update: Update, context: ContextTypes.DEFAULT_TYPE) -> None:
    """Send a message when the command /start is issued."""
    user = update.effective_user
    logger.info(f"User {user.id} ({user.username}) started the bot")
    await update.message.reply_html(
        rf"Hi {user.mention_html()}! Send me a video URL to download.",
    )

async def help_command(update: Update, context: ContextTypes.DEFAULT_TYPE) -> None:
    """Send a message when the command /help is issued."""
    user = update.effective_user
    logger.info(f"User {user.id} ({user.username}) requested help")
    await update.message.reply_text("Send me a video URL, and I'll download it for you!")

def is_url(text):
    """Check if the given text is a URL."""
    url_pattern = re.compile(
        r'http[s]?://(?:[a-zA-Z]|[0-9]|[$-_@.&+]|[!*\\(\\),]|(?:%[0-9a-fA-F][0-9a-fA-F]))+'
    )
    return bool(url_pattern.match(text))

def download_video_task(url, max_retries=3):
    """Download the video from the provided URL with retries."""
    for attempt in range(max_retries):
        try:
            logger.info(f"Starting download attempt {attempt + 1} for URL: {url}")
            ydl_opts = {
                'outtmpl': os.path.join(DOWNLOAD_DIR, '%(title)s.%(ext)s'),
                'format': 'bestaudio/best',
                'postprocessors': [{
                    'key': 'FFmpegExtractAudio',
                    'preferredcodec': 'mp3',
                    'preferredquality': '192',
                }],
                'logger': logger,
                'progress_hooks': [lambda d: logger.info(f'Download progress: {d["_percent_str"]} of {d["_total_bytes_str"]}')],
            }
            with yt_dlp.YoutubeDL(ydl_opts) as ydl:
                info = ydl.extract_info(url, download=True)
                filename = ydl.prepare_filename(info)
                filename = os.path.splitext(filename)[0] + '.mp3'  # Change extension to mp3
            logger.info(f"Download completed successfully: {filename}")
            return filename
        except Exception as e:
            logger.error(f"Download attempt {attempt + 1} failed: {str(e)}")
            if attempt == max_retries - 1:
                raise
            logger.info(f"Waiting 5 seconds before retry...")
            time.sleep(5)  # Wait for 5 seconds before retrying

async def download_video(update: Update, context: ContextTypes.DEFAULT_TYPE) -> None:
    """Handle video download request."""
    user = update.effective_user
    message_text = update.message.text
    logger.info(f"Received message from user {user.id} ({user.username}): {message_text}")
    if is_url(message_text):
        await update.message.reply_text("Starting download. Please wait...")
        try:
            logger.info(f"Starting download process for URL: {message_text}")
            filename = await context.application.loop.run_in_executor(
                executor, download_video_task, message_text)
            
            logger.info(f"Sending file to user: {filename}")
            # Send the downloaded file
            await update.message.reply_document(document=open(filename, 'rb'))
            
            logger.info(f"Deleting file: {filename}")
            # Delete the file after sending
            os.remove(filename)
2024-07-22 14:33:16,591 - __main__ - WARNING - User 2042811943 (None) sent invalid URL: import logging
import re
import os
from telegram import Update
from telegram.ext import Application, CommandHandler, ContextTypes, MessageHandler, filters
import yt_dlp
from dotenv import load_dotenv
import concurrent.futures
import time
import sys

# 加载.env文件中的环境变量
load_dotenv()

# 将环境变量中的token赋值给TOKEN
TOKEN = os.getenv('TELEGRAM_BOT_TOKEN')

# 设置下载目录
DOWNLOAD_DIR = 'downloads'
if not os.path.exists(DOWNLOAD_DIR):
    os.makedirs(DOWNLOAD_DIR)

# 配置日志记录
logging.basicConfig(
    level=logging.INFO,
    format="%(asctime)s - %(name)s - %(levelname)s - %(message)s",
    handlers=[
        logging.FileHandler("bot.log"),
        logging.StreamHandler(sys.stdout)
    ]
)

logger = logging.getLogger(__name__)

# 创建线程池
executor = concurrent.futures.ThreadPoolExecutor(max_workers=5)

async def start(update: Update, context: ContextTypes.DEFAULT_TYPE) -> None:
    """Send a message when the command /start is issued."""
    user = update.effective_user
    logger.info(f"User {user.id} ({user.username}) started the bot")
    await update.message.reply_html(
        rf"Hi {user.mention_html()}! Send me a video URL to download.",
    )

async def help_command(update: Update, context: ContextTypes.DEFAULT_TYPE) -> None:
    """Send a message when the command /help is issued."""
    user = update.effective_user
    logger.info(f"User {user.id} ({user.username}) requested help")
    await update.message.reply_text("Send me a video URL, and I'll download it for you!")

def is_url(text):
    """Check if the given text is a URL."""
    url_pattern = re.compile(
        r'http[s]?://(?:[a-zA-Z]|[0-9]|[$-_@.&+]|[!*\\(\\),]|(?:%[0-9a-fA-F][0-9a-fA-F]))+'
    )
    return bool(url_pattern.match(text))

def download_video_task(url, max_retries=3):
    """Download the video from the provided URL with retries."""
    for attempt in range(max_retries):
        try:
            logger.info(f"Starting download attempt {attempt + 1} for URL: {url}")
            ydl_opts = {
                'outtmpl': os.path.join(DOWNLOAD_DIR, '%(title)s.%(ext)s'),
                'format': 'bestaudio/best',
                'postprocessors': [{
                    'key': 'FFmpegExtractAudio',
                    'preferredcodec': 'mp3',
                    'preferredquality': '192',
                }],
                'logger': logger,
                'progress_hooks': [lambda d: logger.info(f'Download progress: {d["_percent_str"]} of {d["_total_bytes_str"]}')],
            }
            with yt_dlp.YoutubeDL(ydl_opts) as ydl:
                info = ydl.extract_info(url, download=True)
                filename = ydl.prepare_filename(info)
                filename = os.path.splitext(filename)[0] + '.mp3'  # Change extension to mp3
            logger.info(f"Download completed successfully: {filename}")
            return filename
        except Exception as e:
            logger.error(f"Download attempt {attempt + 1} failed: {str(e)}")
            if attempt == max_retries - 1:
                raise
            logger.info(f"Waiting 5 seconds before retry...")
            time.sleep(5)  # Wait for 5 seconds before retrying

async def download_video(update: Update, context: ContextTypes.DEFAULT_TYPE) -> None:
    """Handle video download request."""
    user = update.effective_user
    message_text = update.message.text
    logger.info(f"Received message from user {user.id} ({user.username}): {message_text}")
    if is_url(message_text):
        await update.message.reply_text("Starting download. Please wait...")
        try:
            logger.info(f"Starting download process for URL: {message_text}")
            filename = await context.application.loop.run_in_executor(
                executor, download_video_task, message_text)
            
            logger.info(f"Sending file to user: {filename}")
            # Send the downloaded file
            await update.message.reply_document(document=open(filename, 'rb'))
            
            logger.info(f"Deleting file: {filename}")
            # Delete the file after sending
            os.remove(filename)
2024-07-22 14:33:16,850 - httpx - INFO - HTTP Request: POST https://api.telegram.org/bot7064977852:AAGEEutTl0D6gVt-Jgz4aXJ4mxK8mLPdL_E/getUpdates "HTTP/1.1 200 OK"
2024-07-22 14:33:17,964 - httpx - INFO - HTTP Request: POST https://api.telegram.org/bot7064977852:AAGEEutTl0D6gVt-Jgz4aXJ4mxK8mLPdL_E/sendMessage "HTTP/1.1 200 OK"
2024-07-22 14:33:17,966 - __main__ - INFO - Received message from user 2042811943 (None): logger.info("Download and send process completed successfully")
            await update.message.reply_text("Download completed and file sent!")
        except Exception as e:
            logger.error(f"Failed to download after 3 attempts: {str(e)}")
            await update.message.reply_text(f"Failed to download after 3 attempts. Please try again later.")
    else:
        logger.warning(f"User {user.id} ({user.username}) sent invalid URL: {message_text}")
        await update.message.reply_text("This is not a valid URL. Please send a video URL.")

def main() -> None:
    """Start the bot."""
    logger.info("Starting the bot")
    application = Application.builder().token(TOKEN).build()
    application.add_handler(CommandHandler("start", start))
    application.add_handler(CommandHandler("help", help_command))
    application.add_handler(MessageHandler(filters.TEXT & ~filters.COMMAND, download_video))
    logger.info("Bot is now polling for updates")
    application.run_polling(allowed_updates=Update.ALL_TYPES)

if name == "_
2024-07-22 14:33:17,967 - __main__ - WARNING - User 2042811943 (None) sent invalid URL: logger.info("Download and send process completed successfully")
            await update.message.reply_text("Download completed and file sent!")
        except Exception as e:
            logger.error(f"Failed to download after 3 attempts: {str(e)}")
            await update.message.reply_text(f"Failed to download after 3 attempts. Please try again later.")
    else:
        logger.warning(f"User {user.id} ({user.username}) sent invalid URL: {message_text}")
        await update.message.reply_text("This is not a valid URL. Please send a video URL.")

def main() -> None:
    """Start the bot."""
    logger.info("Starting the bot")
    application = Application.builder().token(TOKEN).build()
    application.add_handler(CommandHandler("start", start))
    application.add_handler(CommandHandler("help", help_command))
    application.add_handler(MessageHandler(filters.TEXT & ~filters.COMMAND, download_video))
    logger.info("Bot is now polling for updates")
    application.run_polling(allowed_updates=Update.ALL_TYPES)

if name == "_
2024-07-22 14:33:18,437 - httpx - INFO - HTTP Request: POST https://api.telegram.org/bot7064977852:AAGEEutTl0D6gVt-Jgz4aXJ4mxK8mLPdL_E/sendMessage "HTTP/1.1 200 OK"
2024-07-22 14:33:27,104 - httpx - INFO - HTTP Request: POST https://api.telegram.org/bot7064977852:AAGEEutTl0D6gVt-Jgz4aXJ4mxK8mLPdL_E/getUpdates "HTTP/1.1 200 OK"
2024-07-22 14:33:37,378 - httpx - INFO - HTTP Request: POST https://api.telegram.org/bot7064977852:AAGEEutTl0D6gVt-Jgz4aXJ4mxK8mLPdL_E/getUpdates "HTTP/1.1 200 OK"
2024-07-22 14:33:39,486 - httpx - INFO - HTTP Request: POST https://api.telegram.org/bot7064977852:AAGEEutTl0D6gVt-Jgz4aXJ4mxK8mLPdL_E/getUpdates "HTTP/1.1 200 OK"
2024-07-22 14:33:39,487 - __main__ - INFO - Received message from user 2042811943 (None): https://youtube.com/shorts/cnGJ86yf0cM?si=RlZ0yX6baDDHjUJF
2024-07-22 14:33:40,799 - httpx - INFO - HTTP Request: POST https://api.telegram.org/bot7064977852:AAGEEutTl0D6gVt-Jgz4aXJ4mxK8mLPdL_E/sendMessage "HTTP/1.1 200 OK"
2024-07-22 14:33:40,801 - __main__ - INFO - Starting download process for URL: https://youtube.com/shorts/cnGJ86yf0cM?si=RlZ0yX6baDDHjUJF
2024-07-22 14:33:40,801 - __main__ - ERROR - Failed to download after 3 attempts: 'Application' object has no attribute 'loop'
2024-07-22 14:33:41,292 - httpx - INFO - HTTP Request: POST https://api.telegram.org/bot7064977852:AAGEEutTl0D6gVt-Jgz4aXJ4mxK8mLPdL_E/sendMessage "HTTP/1.1 200 OK"
2024-07-22 14:33:49,741 - httpx - INFO - HTTP Request: POST https://api.telegram.org/bot7064977852:AAGEEutTl0D6gVt-Jgz4aXJ4mxK8mLPdL_E/getUpdates "HTTP/1.1 200 OK"
2024-07-22 14:34:00,000 - httpx - INFO - HTTP Request: POST https://api.telegram.org/bot7064977852:AAGEEutTl0D6gVt-Jgz4aXJ4mxK8mLPdL_E/getUpdates "HTTP/1.1 200 OK"
2024-07-22 14:34:10,279 - httpx - INFO - HTTP Request: POST https://api.telegram.org/bot7064977852:AAGEEutTl0D6gVt-Jgz4aXJ4mxK8mLPdL_E/getUpdates "HTTP/1.1 200 OK"
2024-07-22 14:34:20,537 - httpx - INFO - HTTP Request: POST https://api.telegram.org/bot7064977852:AAGEEutTl0D6gVt-Jgz4aXJ4mxK8mLPdL_E/getUpdates "HTTP/1.1 200 OK"
2024-07-22 14:34:30,791 - httpx - INFO - HTTP Request: POST https://api.telegram.org/bot7064977852:AAGEEutTl0D6gVt-Jgz4aXJ4mxK8mLPdL_E/getUpdates "HTTP/1.1 200 OK"
2024-07-22 14:34:41,043 - httpx - INFO - HTTP Request: POST https://api.telegram.org/bot7064977852:AAGEEutTl0D6gVt-Jgz4aXJ4mxK8mLPdL_E/getUpdates "HTTP/1.1 200 OK"
2024-07-22 14:34:51,303 - httpx - INFO - HTTP Request: POST https://api.telegram.org/bot7064977852:AAGEEutTl0D6gVt-Jgz4aXJ4mxK8mLPdL_E/getUpdates "HTTP/1.1 200 OK"
2024-07-22 14:35:01,571 - httpx - INFO - HTTP Request: POST https://api.telegram.org/bot7064977852:AAGEEutTl0D6gVt-Jgz4aXJ4mxK8mLPdL_E/getUpdates "HTTP/1.1 200 OK"
2024-07-22 14:35:11,824 - httpx - INFO - HTTP Request: POST https://api.telegram.org/bot7064977852:AAGEEutTl0D6gVt-Jgz4aXJ4mxK8mLPdL_E/getUpdates "HTTP/1.1 200 OK"
2024-07-22 14:35:57,676 - __main__ - INFO - Starting the bot
2024-07-22 14:35:57,763 - __main__ - INFO - Bot is now polling for updates
2024-07-22 14:35:58,997 - httpx - INFO - HTTP Request: POST https://api.telegram.org/bot7064977852:AAGEEutTl0D6gVt-Jgz4aXJ4mxK8mLPdL_E/getMe "HTTP/1.1 200 OK"
2024-07-22 14:35:59,301 - httpx - INFO - HTTP Request: POST https://api.telegram.org/bot7064977852:AAGEEutTl0D6gVt-Jgz4aXJ4mxK8mLPdL_E/deleteWebhook "HTTP/1.1 200 OK"
2024-07-22 14:35:59,304 - telegram.ext.Application - INFO - Application started
2024-07-22 14:36:10,579 - httpx - INFO - HTTP Request: POST https://api.telegram.org/bot7064977852:AAGEEutTl0D6gVt-Jgz4aXJ4mxK8mLPdL_E/getUpdates "HTTP/1.1 200 OK"
2024-07-22 14:36:20,872 - httpx - INFO - HTTP Request: POST https://api.telegram.org/bot7064977852:AAGEEutTl0D6gVt-Jgz4aXJ4mxK8mLPdL_E/getUpdates "HTTP/1.1 200 OK"
2024-07-22 14:36:31,159 - httpx - INFO - HTTP Request: POST https://api.telegram.org/bot7064977852:AAGEEutTl0D6gVt-Jgz4aXJ4mxK8mLPdL_E/getUpdates "HTTP/1.1 200 OK"
2024-07-22 14:36:42,020 - httpx - INFO - HTTP Request: POST https://api.telegram.org/bot7064977852:AAGEEutTl0D6gVt-Jgz4aXJ4mxK8mLPdL_E/getUpdates "HTTP/1.1 200 OK"
2024-07-22 14:36:52,294 - httpx - INFO - HTTP Request: POST https://api.telegram.org/bot7064977852:AAGEEutTl0D6gVt-Jgz4aXJ4mxK8mLPdL_E/getUpdates "HTTP/1.1 200 OK"
2024-07-22 14:37:02,548 - httpx - INFO - HTTP Request: POST https://api.telegram.org/bot7064977852:AAGEEutTl0D6gVt-Jgz4aXJ4mxK8mLPdL_E/getUpdates "HTTP/1.1 200 OK"
2024-07-22 14:37:12,803 - httpx - INFO - HTTP Request: POST https://api.telegram.org/bot7064977852:AAGEEutTl0D6gVt-Jgz4aXJ4mxK8mLPdL_E/getUpdates "HTTP/1.1 200 OK"
2024-07-22 14:37:23,066 - httpx - INFO - HTTP Request: POST https://api.telegram.org/bot7064977852:AAGEEutTl0D6gVt-Jgz4aXJ4mxK8mLPdL_E/getUpdates "HTTP/1.1 200 OK"
2024-07-22 14:37:33,367 - httpx - INFO - HTTP Request: POST https://api.telegram.org/bot7064977852:AAGEEutTl0D6gVt-Jgz4aXJ4mxK8mLPdL_E/getUpdates "HTTP/1.1 200 OK"
2024-07-22 14:37:33,981 - httpx - INFO - HTTP Request: POST https://api.telegram.org/bot7064977852:AAGEEutTl0D6gVt-Jgz4aXJ4mxK8mLPdL_E/getUpdates "HTTP/1.1 200 OK"
2024-07-22 14:37:33,983 - __main__ - INFO - Received message from user 2042811943 (None): https://youtube.com/shorts/cnGJ86yf0cM?si=RlZ0yX6baDDHjUJF
2024-07-22 14:37:35,329 - httpx - INFO - HTTP Request: POST https://api.telegram.org/bot7064977852:AAGEEutTl0D6gVt-Jgz4aXJ4mxK8mLPdL_E/sendMessage "HTTP/1.1 200 OK"
2024-07-22 14:37:35,333 - __main__ - INFO - Starting download process for URL: https://youtube.com/shorts/cnGJ86yf0cM?si=RlZ0yX6baDDHjUJF
2024-07-22 14:37:35,333 - __main__ - INFO - Starting download attempt 1 for URL: https://youtube.com/shorts/cnGJ86yf0cM?si=RlZ0yX6baDDHjUJF
2024-07-22 14:37:44,253 - httpx - INFO - HTTP Request: POST https://api.telegram.org/bot7064977852:AAGEEutTl0D6gVt-Jgz4aXJ4mxK8mLPdL_E/getUpdates "HTTP/1.1 200 OK"
2024-07-22 14:37:54,545 - httpx - INFO - HTTP Request: POST https://api.telegram.org/bot7064977852:AAGEEutTl0D6gVt-Jgz4aXJ4mxK8mLPdL_E/getUpdates "HTTP/1.1 200 OK"
2024-07-22 14:37:55,912 - __main__ - WARNING - [youtube] Unable to download webpage: HTTPSConnectionPool(host='www.youtube.com', port=443): Read timed out. (read timeout=20.0)
2024-07-22 14:38:04,799 - httpx - INFO - HTTP Request: POST https://api.telegram.org/bot7064977852:AAGEEutTl0D6gVt-Jgz4aXJ4mxK8mLPdL_E/getUpdates "HTTP/1.1 200 OK"
2024-07-22 14:38:15,050 - httpx - INFO - HTTP Request: POST https://api.telegram.org/bot7064977852:AAGEEutTl0D6gVt-Jgz4aXJ4mxK8mLPdL_E/getUpdates "HTTP/1.1 200 OK"
2024-07-22 14:38:16,050 - __main__ - WARNING - [youtube] HTTPSConnectionPool(host='www.youtube.com', port=443): Read timed out. (read timeout=20.0). Retrying (1/3)...
2024-07-22 14:38:25,796 - httpx - INFO - HTTP Request: POST https://api.telegram.org/bot7064977852:AAGEEutTl0D6gVt-Jgz4aXJ4mxK8mLPdL_E/getUpdates "HTTP/1.1 200 OK"
2024-07-22 14:38:36,050 - httpx - INFO - HTTP Request: POST https://api.telegram.org/bot7064977852:AAGEEutTl0D6gVt-Jgz4aXJ4mxK8mLPdL_E/getUpdates "HTTP/1.1 200 OK"
2024-07-22 14:38:36,152 - __main__ - WARNING - [youtube] HTTPSConnectionPool(host='www.youtube.com', port=443): Read timed out. (read timeout=20.0). Retrying (2/3)...
2024-07-22 14:38:46,309 - httpx - INFO - HTTP Request: POST https://api.telegram.org/bot7064977852:AAGEEutTl0D6gVt-Jgz4aXJ4mxK8mLPdL_E/getUpdates "HTTP/1.1 200 OK"
2024-07-22 14:38:56,253 - __main__ - WARNING - [youtube] HTTPSConnectionPool(host='www.youtube.com', port=443): Read timed out. (read timeout=20.0). Retrying (3/3)...
2024-07-22 14:38:56,562 - httpx - INFO - HTTP Request: POST https://api.telegram.org/bot7064977852:AAGEEutTl0D6gVt-Jgz4aXJ4mxK8mLPdL_E/getUpdates "HTTP/1.1 200 OK"
2024-07-22 14:39:06,816 - httpx - INFO - HTTP Request: POST https://api.telegram.org/bot7064977852:AAGEEutTl0D6gVt-Jgz4aXJ4mxK8mLPdL_E/getUpdates "HTTP/1.1 200 OK"
2024-07-22 14:39:16,449 - __main__ - WARNING - [youtube] Unable to download API page: HTTPSConnectionPool(host='www.youtube.com', port=443): Read timed out. (read timeout=20.0) (caused by TransportError("HTTPSConnectionPool(host='www.youtube.com', port=443): Read timed out. (read timeout=20.0)"))
2024-07-22 14:39:17,062 - httpx - INFO - HTTP Request: POST https://api.telegram.org/bot7064977852:AAGEEutTl0D6gVt-Jgz4aXJ4mxK8mLPdL_E/getUpdates "HTTP/1.1 200 OK"
2024-07-22 14:39:27,318 - httpx - INFO - HTTP Request: POST https://api.telegram.org/bot7064977852:AAGEEutTl0D6gVt-Jgz4aXJ4mxK8mLPdL_E/getUpdates "HTTP/1.1 200 OK"
2024-07-22 14:44:15,465 - __main__ - INFO - Starting the bot
2024-07-22 14:44:57,039 - __main__ - INFO - Starting the bot
2024-07-22 14:48:28,036 - __main__ - INFO - Starting the bot
2024-07-22 14:48:28,242 - __main__ - INFO - Bot is now polling for updates
2024-07-22 14:48:36,905 - __main__ - INFO - Starting the bot
2024-07-22 14:48:37,124 - __main__ - INFO - Bot is now polling for updates
2024-07-22 14:56:53,018 - __main__ - INFO - Starting the bot
2024-07-22 14:56:53,147 - __main__ - INFO - Bot is now polling for updates
2024-07-22 15:04:58,201 - __main__ - INFO - Starting the bot
2024-07-22 15:04:58,331 - __main__ - INFO - Bot is now polling for updates
2024-07-22 15:05:06,319 - __main__ - INFO - Starting the bot
2024-07-22 15:05:06,444 - __main__ - INFO - Bot is now polling for updates
2024-07-22 15:05:08,150 - httpx - INFO - HTTP Request: POST https://api.telegram.org/bot7064977852:AAGEEutTl0D6gVt-Jgz4aXJ4mxK8mLPdL_E/getMe "HTTP/1.1 200 OK"
2024-07-22 15:05:08,534 - httpx - INFO - HTTP Request: POST https://api.telegram.org/bot7064977852:AAGEEutTl0D6gVt-Jgz4aXJ4mxK8mLPdL_E/deleteWebhook "HTTP/1.1 200 OK"
2024-07-22 15:05:08,538 - telegram.ext.Application - INFO - Application started
2024-07-22 15:08:29,802 - httpx - INFO - HTTP Request: POST https://api.telegram.org/bot7064977852:AAGEEutTl0D6gVt-Jgz4aXJ4mxK8mLPdL_E/getUpdates "HTTP/1.1 200 OK"
2024-07-22 15:08:29,820 - __main__ - INFO - Received message from user 2042811943 (None): https://youtube.com/shorts/cnGJ86yf0cM?si=RlZ0yX6baDDHjUJF
2024-07-22 15:08:30,528 - httpx - INFO - HTTP Request: POST https://api.telegram.org/bot7064977852:AAGEEutTl0D6gVt-Jgz4aXJ4mxK8mLPdL_E/getUpdates "HTTP/1.1 200 OK"
2024-07-22 15:08:34,833 - telegram.ext.Application - ERROR - No error handlers are registered, logging exception.
Traceback (most recent call last):
  File "/Users/airhao3/miniconda3/envs/bot/lib/python3.10/site-packages/httpx/_transports/default.py", line 69, in map_httpcore_exceptions
    yield
  File "/Users/airhao3/miniconda3/envs/bot/lib/python3.10/site-packages/httpx/_transports/default.py", line 373, in handle_async_request
    resp = await self._pool.handle_async_request(req)
  File "/Users/airhao3/miniconda3/envs/bot/lib/python3.10/site-packages/httpcore/_async/connection_pool.py", line 216, in handle_async_request
    raise exc from None
  File "/Users/airhao3/miniconda3/envs/bot/lib/python3.10/site-packages/httpcore/_async/connection_pool.py", line 196, in handle_async_request
    response = await connection.handle_async_request(
  File "/Users/airhao3/miniconda3/envs/bot/lib/python3.10/site-packages/httpcore/_async/socks_proxy.py", line 296, in handle_async_request
    raise exc
  File "/Users/airhao3/miniconda3/envs/bot/lib/python3.10/site-packages/httpcore/_async/socks_proxy.py", line 267, in handle_async_request
    stream = await stream.start_tls(**kwargs)
  File "/Users/airhao3/miniconda3/envs/bot/lib/python3.10/site-packages/httpcore/_backends/anyio.py", line 68, in start_tls
    with map_exceptions(exc_map):
  File "/Users/airhao3/miniconda3/envs/bot/lib/python3.10/contextlib.py", line 153, in __exit__
    self.gen.throw(typ, value, traceback)
  File "/Users/airhao3/miniconda3/envs/bot/lib/python3.10/site-packages/httpcore/_exceptions.py", line 14, in map_exceptions
    raise to_exc(exc) from exc
httpcore.ConnectTimeout

The above exception was the direct cause of the following exception:

Traceback (most recent call last):
  File "/Users/airhao3/miniconda3/envs/bot/lib/python3.10/site-packages/telegram/request/_httpxrequest.py", line 276, in do_request
    res = await self._client.request(
  File "/Users/airhao3/miniconda3/envs/bot/lib/python3.10/site-packages/httpx/_client.py", line 1574, in request
    return await self.send(request, auth=auth, follow_redirects=follow_redirects)
  File "/Users/airhao3/miniconda3/envs/bot/lib/python3.10/site-packages/httpx/_client.py", line 1661, in send
    response = await self._send_handling_auth(
  File "/Users/airhao3/miniconda3/envs/bot/lib/python3.10/site-packages/httpx/_client.py", line 1689, in _send_handling_auth
    response = await self._send_handling_redirects(
  File "/Users/airhao3/miniconda3/envs/bot/lib/python3.10/site-packages/httpx/_client.py", line 1726, in _send_handling_redirects
    response = await self._send_single_request(request)
  File "/Users/airhao3/miniconda3/envs/bot/lib/python3.10/site-packages/httpx/_client.py", line 1763, in _send_single_request
    response = await transport.handle_async_request(request)
  File "/Users/airhao3/miniconda3/envs/bot/lib/python3.10/site-packages/httpx/_transports/default.py", line 372, in handle_async_request
    with map_httpcore_exceptions():
  File "/Users/airhao3/miniconda3/envs/bot/lib/python3.10/contextlib.py", line 153, in __exit__
    self.gen.throw(typ, value, traceback)
  File "/Users/airhao3/miniconda3/envs/bot/lib/python3.10/site-packages/httpx/_transports/default.py", line 86, in map_httpcore_exceptions
    raise mapped_exc(message) from exc
httpx.ConnectTimeout

The above exception was the direct cause of the following exception:

Traceback (most recent call last):
  File "/Users/airhao3/miniconda3/envs/bot/lib/python3.10/site-packages/telegram/ext/_application.py", line 1335, in process_update
    await coroutine
  File "/Users/airhao3/miniconda3/envs/bot/lib/python3.10/site-packages/telegram/ext/_handlers/basehandler.py", line 157, in handle_update
    return await self.callback(update, context)
  File "/Users/airhao3/nextcloud/document/telegram-bot-python/telegram-bot-download-proxy.py", line 109, in download_video
    status_message = await update.message.reply_text("Starting download. Please wait...")
  File "/Users/airhao3/miniconda3/envs/bot/lib/python3.10/site-packages/telegram/_message.py", line 1763, in reply_text
    return await self.get_bot().send_message(
  File "/Users/airhao3/miniconda3/envs/bot/lib/python3.10/site-packages/telegram/ext/_extbot.py", line 2907, in send_message
    return await super().send_message(
  File "/Users/airhao3/miniconda3/envs/bot/lib/python3.10/site-packages/telegram/_bot.py", line 1028, in send_message
    return await self._send_message(
  File "/Users/airhao3/miniconda3/envs/bot/lib/python3.10/site-packages/telegram/ext/_extbot.py", line 610, in _send_message
    result = await super()._send_message(
  File "/Users/airhao3/miniconda3/envs/bot/lib/python3.10/site-packages/telegram/_bot.py", line 744, in _send_message
    result = await self._post(
  File "/Users/airhao3/miniconda3/envs/bot/lib/python3.10/site-packages/telegram/_bot.py", line 622, in _post
    return await self._do_post(
  File "/Users/airhao3/miniconda3/envs/bot/lib/python3.10/site-packages/telegram/ext/_extbot.py", line 355, in _do_post
    return await super()._do_post(
  File "/Users/airhao3/miniconda3/envs/bot/lib/python3.10/site-packages/telegram/_bot.py", line 651, in _do_post
    result = await request.post(
  File "/Users/airhao3/miniconda3/envs/bot/lib/python3.10/site-packages/telegram/request/_baserequest.py", line 200, in post
    result = await self._request_wrapper(
  File "/Users/airhao3/miniconda3/envs/bot/lib/python3.10/site-packages/telegram/request/_baserequest.py", line 342, in _request_wrapper
    raise exc
  File "/Users/airhao3/miniconda3/envs/bot/lib/python3.10/site-packages/telegram/request/_baserequest.py", line 332, in _request_wrapper
    code, payload = await self.do_request(
  File "/Users/airhao3/miniconda3/envs/bot/lib/python3.10/site-packages/telegram/request/_httpxrequest.py", line 293, in do_request
    raise TimedOut from err
telegram.error.TimedOut: Timed out
2024-07-22 15:08:34,861 - __main__ - INFO - Received message from user 2042811943 (None): hi
2024-07-22 15:08:34,862 - __main__ - WARNING - User 2042811943 (None) sent invalid URL: hi
2024-07-22 15:08:39,866 - telegram.ext.Application - ERROR - No error handlers are registered, logging exception.
Traceback (most recent call last):
  File "/Users/airhao3/miniconda3/envs/bot/lib/python3.10/site-packages/httpx/_transports/default.py", line 69, in map_httpcore_exceptions
    yield
  File "/Users/airhao3/miniconda3/envs/bot/lib/python3.10/site-packages/httpx/_transports/default.py", line 373, in handle_async_request
    resp = await self._pool.handle_async_request(req)
  File "/Users/airhao3/miniconda3/envs/bot/lib/python3.10/site-packages/httpcore/_async/connection_pool.py", line 216, in handle_async_request
    raise exc from None
  File "/Users/airhao3/miniconda3/envs/bot/lib/python3.10/site-packages/httpcore/_async/connection_pool.py", line 196, in handle_async_request
    response = await connection.handle_async_request(
  File "/Users/airhao3/miniconda3/envs/bot/lib/python3.10/site-packages/httpcore/_async/socks_proxy.py", line 296, in handle_async_request
    raise exc
  File "/Users/airhao3/miniconda3/envs/bot/lib/python3.10/site-packages/httpcore/_async/socks_proxy.py", line 267, in handle_async_request
    stream = await stream.start_tls(**kwargs)
  File "/Users/airhao3/miniconda3/envs/bot/lib/python3.10/site-packages/httpcore/_backends/anyio.py", line 68, in start_tls
    with map_exceptions(exc_map):
  File "/Users/airhao3/miniconda3/envs/bot/lib/python3.10/contextlib.py", line 153, in __exit__
    self.gen.throw(typ, value, traceback)
  File "/Users/airhao3/miniconda3/envs/bot/lib/python3.10/site-packages/httpcore/_exceptions.py", line 14, in map_exceptions
    raise to_exc(exc) from exc
httpcore.ConnectTimeout

The above exception was the direct cause of the following exception:

Traceback (most recent call last):
  File "/Users/airhao3/miniconda3/envs/bot/lib/python3.10/site-packages/telegram/request/_httpxrequest.py", line 276, in do_request
    res = await self._client.request(
  File "/Users/airhao3/miniconda3/envs/bot/lib/python3.10/site-packages/httpx/_client.py", line 1574, in request
    return await self.send(request, auth=auth, follow_redirects=follow_redirects)
  File "/Users/airhao3/miniconda3/envs/bot/lib/python3.10/site-packages/httpx/_client.py", line 1661, in send
    response = await self._send_handling_auth(
  File "/Users/airhao3/miniconda3/envs/bot/lib/python3.10/site-packages/httpx/_client.py", line 1689, in _send_handling_auth
    response = await self._send_handling_redirects(
  File "/Users/airhao3/miniconda3/envs/bot/lib/python3.10/site-packages/httpx/_client.py", line 1726, in _send_handling_redirects
    response = await self._send_single_request(request)
  File "/Users/airhao3/miniconda3/envs/bot/lib/python3.10/site-packages/httpx/_client.py", line 1763, in _send_single_request
    response = await transport.handle_async_request(request)
  File "/Users/airhao3/miniconda3/envs/bot/lib/python3.10/site-packages/httpx/_transports/default.py", line 372, in handle_async_request
    with map_httpcore_exceptions():
  File "/Users/airhao3/miniconda3/envs/bot/lib/python3.10/contextlib.py", line 153, in __exit__
    self.gen.throw(typ, value, traceback)
  File "/Users/airhao3/miniconda3/envs/bot/lib/python3.10/site-packages/httpx/_transports/default.py", line 86, in map_httpcore_exceptions
    raise mapped_exc(message) from exc
httpx.ConnectTimeout

The above exception was the direct cause of the following exception:

Traceback (most recent call last):
  File "/Users/airhao3/miniconda3/envs/bot/lib/python3.10/site-packages/telegram/ext/_application.py", line 1335, in process_update
    await coroutine
  File "/Users/airhao3/miniconda3/envs/bot/lib/python3.10/site-packages/telegram/ext/_handlers/basehandler.py", line 157, in handle_update
    return await self.callback(update, context)
  File "/Users/airhao3/nextcloud/document/telegram-bot-python/telegram-bot-download-proxy.py", line 130, in download_video
    await update.message.reply_text("This is not a valid URL. Please send a video URL.")
  File "/Users/airhao3/miniconda3/envs/bot/lib/python3.10/site-packages/telegram/_message.py", line 1763, in reply_text
    return await self.get_bot().send_message(
  File "/Users/airhao3/miniconda3/envs/bot/lib/python3.10/site-packages/telegram/ext/_extbot.py", line 2907, in send_message
    return await super().send_message(
  File "/Users/airhao3/miniconda3/envs/bot/lib/python3.10/site-packages/telegram/_bot.py", line 1028, in send_message
    return await self._send_message(
  File "/Users/airhao3/miniconda3/envs/bot/lib/python3.10/site-packages/telegram/ext/_extbot.py", line 610, in _send_message
    result = await super()._send_message(
  File "/Users/airhao3/miniconda3/envs/bot/lib/python3.10/site-packages/telegram/_bot.py", line 744, in _send_message
    result = await self._post(
  File "/Users/airhao3/miniconda3/envs/bot/lib/python3.10/site-packages/telegram/_bot.py", line 622, in _post
    return await self._do_post(
  File "/Users/airhao3/miniconda3/envs/bot/lib/python3.10/site-packages/telegram/ext/_extbot.py", line 355, in _do_post
    return await super()._do_post(
  File "/Users/airhao3/miniconda3/envs/bot/lib/python3.10/site-packages/telegram/_bot.py", line 651, in _do_post
    result = await request.post(
  File "/Users/airhao3/miniconda3/envs/bot/lib/python3.10/site-packages/telegram/request/_baserequest.py", line 200, in post
    result = await self._request_wrapper(
  File "/Users/airhao3/miniconda3/envs/bot/lib/python3.10/site-packages/telegram/request/_baserequest.py", line 342, in _request_wrapper
    raise exc
  File "/Users/airhao3/miniconda3/envs/bot/lib/python3.10/site-packages/telegram/request/_baserequest.py", line 332, in _request_wrapper
    code, payload = await self.do_request(
  File "/Users/airhao3/miniconda3/envs/bot/lib/python3.10/site-packages/telegram/request/_httpxrequest.py", line 293, in do_request
    raise TimedOut from err
telegram.error.TimedOut: Timed out
2024-07-22 15:08:39,870 - __main__ - INFO - User 2042811943 (None) started the bot
2024-07-22 15:08:40,878 - httpx - INFO - HTTP Request: POST https://api.telegram.org/bot7064977852:AAGEEutTl0D6gVt-Jgz4aXJ4mxK8mLPdL_E/getUpdates "HTTP/1.1 200 OK"
2024-07-22 15:08:44,875 - telegram.ext.Application - ERROR - No error handlers are registered, logging exception.
Traceback (most recent call last):
  File "/Users/airhao3/miniconda3/envs/bot/lib/python3.10/site-packages/httpx/_transports/default.py", line 69, in map_httpcore_exceptions
    yield
  File "/Users/airhao3/miniconda3/envs/bot/lib/python3.10/site-packages/httpx/_transports/default.py", line 373, in handle_async_request
    resp = await self._pool.handle_async_request(req)
  File "/Users/airhao3/miniconda3/envs/bot/lib/python3.10/site-packages/httpcore/_async/connection_pool.py", line 216, in handle_async_request
    raise exc from None
  File "/Users/airhao3/miniconda3/envs/bot/lib/python3.10/site-packages/httpcore/_async/connection_pool.py", line 196, in handle_async_request
    response = await connection.handle_async_request(
  File "/Users/airhao3/miniconda3/envs/bot/lib/python3.10/site-packages/httpcore/_async/socks_proxy.py", line 296, in handle_async_request
    raise exc
  File "/Users/airhao3/miniconda3/envs/bot/lib/python3.10/site-packages/httpcore/_async/socks_proxy.py", line 267, in handle_async_request
    stream = await stream.start_tls(**kwargs)
  File "/Users/airhao3/miniconda3/envs/bot/lib/python3.10/site-packages/httpcore/_backends/anyio.py", line 68, in start_tls
    with map_exceptions(exc_map):
  File "/Users/airhao3/miniconda3/envs/bot/lib/python3.10/contextlib.py", line 153, in __exit__
    self.gen.throw(typ, value, traceback)
  File "/Users/airhao3/miniconda3/envs/bot/lib/python3.10/site-packages/httpcore/_exceptions.py", line 14, in map_exceptions
    raise to_exc(exc) from exc
httpcore.ConnectTimeout

The above exception was the direct cause of the following exception:

Traceback (most recent call last):
  File "/Users/airhao3/miniconda3/envs/bot/lib/python3.10/site-packages/telegram/request/_httpxrequest.py", line 276, in do_request
    res = await self._client.request(
  File "/Users/airhao3/miniconda3/envs/bot/lib/python3.10/site-packages/httpx/_client.py", line 1574, in request
    return await self.send(request, auth=auth, follow_redirects=follow_redirects)
  File "/Users/airhao3/miniconda3/envs/bot/lib/python3.10/site-packages/httpx/_client.py", line 1661, in send
    response = await self._send_handling_auth(
  File "/Users/airhao3/miniconda3/envs/bot/lib/python3.10/site-packages/httpx/_client.py", line 1689, in _send_handling_auth
    response = await self._send_handling_redirects(
  File "/Users/airhao3/miniconda3/envs/bot/lib/python3.10/site-packages/httpx/_client.py", line 1726, in _send_handling_redirects
    response = await self._send_single_request(request)
  File "/Users/airhao3/miniconda3/envs/bot/lib/python3.10/site-packages/httpx/_client.py", line 1763, in _send_single_request
    response = await transport.handle_async_request(request)
  File "/Users/airhao3/miniconda3/envs/bot/lib/python3.10/site-packages/httpx/_transports/default.py", line 372, in handle_async_request
    with map_httpcore_exceptions():
  File "/Users/airhao3/miniconda3/envs/bot/lib/python3.10/contextlib.py", line 153, in __exit__
    self.gen.throw(typ, value, traceback)
  File "/Users/airhao3/miniconda3/envs/bot/lib/python3.10/site-packages/httpx/_transports/default.py", line 86, in map_httpcore_exceptions
    raise mapped_exc(message) from exc
httpx.ConnectTimeout

The above exception was the direct cause of the following exception:

Traceback (most recent call last):
  File "/Users/airhao3/miniconda3/envs/bot/lib/python3.10/site-packages/telegram/ext/_application.py", line 1335, in process_update
    await coroutine
  File "/Users/airhao3/miniconda3/envs/bot/lib/python3.10/site-packages/telegram/ext/_handlers/basehandler.py", line 157, in handle_update
    return await self.callback(update, context)
  File "/Users/airhao3/nextcloud/document/telegram-bot-python/telegram-bot-download-proxy.py", line 47, in start
    await update.message.reply_html(
  File "/Users/airhao3/miniconda3/envs/bot/lib/python3.10/site-packages/telegram/_message.py", line 2007, in reply_html
    return await self.get_bot().send_message(
  File "/Users/airhao3/miniconda3/envs/bot/lib/python3.10/site-packages/telegram/ext/_extbot.py", line 2907, in send_message
    return await super().send_message(
  File "/Users/airhao3/miniconda3/envs/bot/lib/python3.10/site-packages/telegram/_bot.py", line 1028, in send_message
    return await self._send_message(
  File "/Users/airhao3/miniconda3/envs/bot/lib/python3.10/site-packages/telegram/ext/_extbot.py", line 610, in _send_message
    result = await super()._send_message(
  File "/Users/airhao3/miniconda3/envs/bot/lib/python3.10/site-packages/telegram/_bot.py", line 744, in _send_message
    result = await self._post(
  File "/Users/airhao3/miniconda3/envs/bot/lib/python3.10/site-packages/telegram/_bot.py", line 622, in _post
    return await self._do_post(
  File "/Users/airhao3/miniconda3/envs/bot/lib/python3.10/site-packages/telegram/ext/_extbot.py", line 355, in _do_post
    return await super()._do_post(
  File "/Users/airhao3/miniconda3/envs/bot/lib/python3.10/site-packages/telegram/_bot.py", line 651, in _do_post
    result = await request.post(
  File "/Users/airhao3/miniconda3/envs/bot/lib/python3.10/site-packages/telegram/request/_baserequest.py", line 200, in post
    result = await self._request_wrapper(
  File "/Users/airhao3/miniconda3/envs/bot/lib/python3.10/site-packages/telegram/request/_baserequest.py", line 342, in _request_wrapper
    raise exc
  File "/Users/airhao3/miniconda3/envs/bot/lib/python3.10/site-packages/telegram/request/_baserequest.py", line 332, in _request_wrapper
    code, payload = await self.do_request(
  File "/Users/airhao3/miniconda3/envs/bot/lib/python3.10/site-packages/telegram/request/_httpxrequest.py", line 293, in do_request
    raise TimedOut from err
telegram.error.TimedOut: Timed out
2024-07-22 15:08:44,878 - __main__ - INFO - Received message from user 2042811943 (None): hi
2024-07-22 15:08:44,878 - __main__ - WARNING - User 2042811943 (None) sent invalid URL: hi
2024-07-22 15:08:49,884 - telegram.ext.Application - ERROR - No error handlers are registered, logging exception.
Traceback (most recent call last):
  File "/Users/airhao3/miniconda3/envs/bot/lib/python3.10/site-packages/httpx/_transports/default.py", line 69, in map_httpcore_exceptions
    yield
  File "/Users/airhao3/miniconda3/envs/bot/lib/python3.10/site-packages/httpx/_transports/default.py", line 373, in handle_async_request
    resp = await self._pool.handle_async_request(req)
  File "/Users/airhao3/miniconda3/envs/bot/lib/python3.10/site-packages/httpcore/_async/connection_pool.py", line 216, in handle_async_request
    raise exc from None
  File "/Users/airhao3/miniconda3/envs/bot/lib/python3.10/site-packages/httpcore/_async/connection_pool.py", line 196, in handle_async_request
    response = await connection.handle_async_request(
  File "/Users/airhao3/miniconda3/envs/bot/lib/python3.10/site-packages/httpcore/_async/socks_proxy.py", line 296, in handle_async_request
    raise exc
  File "/Users/airhao3/miniconda3/envs/bot/lib/python3.10/site-packages/httpcore/_async/socks_proxy.py", line 267, in handle_async_request
    stream = await stream.start_tls(**kwargs)
  File "/Users/airhao3/miniconda3/envs/bot/lib/python3.10/site-packages/httpcore/_backends/anyio.py", line 68, in start_tls
    with map_exceptions(exc_map):
  File "/Users/airhao3/miniconda3/envs/bot/lib/python3.10/contextlib.py", line 153, in __exit__
    self.gen.throw(typ, value, traceback)
  File "/Users/airhao3/miniconda3/envs/bot/lib/python3.10/site-packages/httpcore/_exceptions.py", line 14, in map_exceptions
    raise to_exc(exc) from exc
httpcore.ConnectTimeout

The above exception was the direct cause of the following exception:

Traceback (most recent call last):
  File "/Users/airhao3/miniconda3/envs/bot/lib/python3.10/site-packages/telegram/request/_httpxrequest.py", line 276, in do_request
    res = await self._client.request(
  File "/Users/airhao3/miniconda3/envs/bot/lib/python3.10/site-packages/httpx/_client.py", line 1574, in request
    return await self.send(request, auth=auth, follow_redirects=follow_redirects)
  File "/Users/airhao3/miniconda3/envs/bot/lib/python3.10/site-packages/httpx/_client.py", line 1661, in send
    response = await self._send_handling_auth(
  File "/Users/airhao3/miniconda3/envs/bot/lib/python3.10/site-packages/httpx/_client.py", line 1689, in _send_handling_auth
    response = await self._send_handling_redirects(
  File "/Users/airhao3/miniconda3/envs/bot/lib/python3.10/site-packages/httpx/_client.py", line 1726, in _send_handling_redirects
    response = await self._send_single_request(request)
  File "/Users/airhao3/miniconda3/envs/bot/lib/python3.10/site-packages/httpx/_client.py", line 1763, in _send_single_request
    response = await transport.handle_async_request(request)
  File "/Users/airhao3/miniconda3/envs/bot/lib/python3.10/site-packages/httpx/_transports/default.py", line 372, in handle_async_request
    with map_httpcore_exceptions():
  File "/Users/airhao3/miniconda3/envs/bot/lib/python3.10/contextlib.py", line 153, in __exit__
    self.gen.throw(typ, value, traceback)
  File "/Users/airhao3/miniconda3/envs/bot/lib/python3.10/site-packages/httpx/_transports/default.py", line 86, in map_httpcore_exceptions
    raise mapped_exc(message) from exc
httpx.ConnectTimeout

The above exception was the direct cause of the following exception:

Traceback (most recent call last):
  File "/Users/airhao3/miniconda3/envs/bot/lib/python3.10/site-packages/telegram/ext/_application.py", line 1335, in process_update
    await coroutine
  File "/Users/airhao3/miniconda3/envs/bot/lib/python3.10/site-packages/telegram/ext/_handlers/basehandler.py", line 157, in handle_update
    return await self.callback(update, context)
  File "/Users/airhao3/nextcloud/document/telegram-bot-python/telegram-bot-download-proxy.py", line 130, in download_video
    await update.message.reply_text("This is not a valid URL. Please send a video URL.")
  File "/Users/airhao3/miniconda3/envs/bot/lib/python3.10/site-packages/telegram/_message.py", line 1763, in reply_text
    return await self.get_bot().send_message(
  File "/Users/airhao3/miniconda3/envs/bot/lib/python3.10/site-packages/telegram/ext/_extbot.py", line 2907, in send_message
    return await super().send_message(
  File "/Users/airhao3/miniconda3/envs/bot/lib/python3.10/site-packages/telegram/_bot.py", line 1028, in send_message
    return await self._send_message(
  File "/Users/airhao3/miniconda3/envs/bot/lib/python3.10/site-packages/telegram/ext/_extbot.py", line 610, in _send_message
    result = await super()._send_message(
  File "/Users/airhao3/miniconda3/envs/bot/lib/python3.10/site-packages/telegram/_bot.py", line 744, in _send_message
    result = await self._post(
  File "/Users/airhao3/miniconda3/envs/bot/lib/python3.10/site-packages/telegram/_bot.py", line 622, in _post
    return await self._do_post(
  File "/Users/airhao3/miniconda3/envs/bot/lib/python3.10/site-packages/telegram/ext/_extbot.py", line 355, in _do_post
    return await super()._do_post(
  File "/Users/airhao3/miniconda3/envs/bot/lib/python3.10/site-packages/telegram/_bot.py", line 651, in _do_post
    result = await request.post(
  File "/Users/airhao3/miniconda3/envs/bot/lib/python3.10/site-packages/telegram/request/_baserequest.py", line 200, in post
    result = await self._request_wrapper(
  File "/Users/airhao3/miniconda3/envs/bot/lib/python3.10/site-packages/telegram/request/_baserequest.py", line 342, in _request_wrapper
    raise exc
  File "/Users/airhao3/miniconda3/envs/bot/lib/python3.10/site-packages/telegram/request/_baserequest.py", line 332, in _request_wrapper
    code, payload = await self.do_request(
  File "/Users/airhao3/miniconda3/envs/bot/lib/python3.10/site-packages/telegram/request/_httpxrequest.py", line 293, in do_request
    raise TimedOut from err
telegram.error.TimedOut: Timed out
2024-07-22 15:08:49,887 - __main__ - INFO - Received message from user 2042811943 (None): https://google.com
2024-07-22 15:08:51,775 - httpx - INFO - HTTP Request: POST https://api.telegram.org/bot7064977852:AAGEEutTl0D6gVt-Jgz4aXJ4mxK8mLPdL_E/getUpdates "HTTP/1.1 200 OK"
2024-07-22 15:08:54,893 - telegram.ext.Application - ERROR - No error handlers are registered, logging exception.
Traceback (most recent call last):
  File "/Users/airhao3/miniconda3/envs/bot/lib/python3.10/site-packages/httpx/_transports/default.py", line 69, in map_httpcore_exceptions
    yield
  File "/Users/airhao3/miniconda3/envs/bot/lib/python3.10/site-packages/httpx/_transports/default.py", line 373, in handle_async_request
    resp = await self._pool.handle_async_request(req)
  File "/Users/airhao3/miniconda3/envs/bot/lib/python3.10/site-packages/httpcore/_async/connection_pool.py", line 216, in handle_async_request
    raise exc from None
  File "/Users/airhao3/miniconda3/envs/bot/lib/python3.10/site-packages/httpcore/_async/connection_pool.py", line 196, in handle_async_request
    response = await connection.handle_async_request(
  File "/Users/airhao3/miniconda3/envs/bot/lib/python3.10/site-packages/httpcore/_async/socks_proxy.py", line 296, in handle_async_request
    raise exc
  File "/Users/airhao3/miniconda3/envs/bot/lib/python3.10/site-packages/httpcore/_async/socks_proxy.py", line 267, in handle_async_request
    stream = await stream.start_tls(**kwargs)
  File "/Users/airhao3/miniconda3/envs/bot/lib/python3.10/site-packages/httpcore/_backends/anyio.py", line 68, in start_tls
    with map_exceptions(exc_map):
  File "/Users/airhao3/miniconda3/envs/bot/lib/python3.10/contextlib.py", line 153, in __exit__
    self.gen.throw(typ, value, traceback)
  File "/Users/airhao3/miniconda3/envs/bot/lib/python3.10/site-packages/httpcore/_exceptions.py", line 14, in map_exceptions
    raise to_exc(exc) from exc
httpcore.ConnectTimeout

The above exception was the direct cause of the following exception:

Traceback (most recent call last):
  File "/Users/airhao3/miniconda3/envs/bot/lib/python3.10/site-packages/telegram/request/_httpxrequest.py", line 276, in do_request
    res = await self._client.request(
  File "/Users/airhao3/miniconda3/envs/bot/lib/python3.10/site-packages/httpx/_client.py", line 1574, in request
    return await self.send(request, auth=auth, follow_redirects=follow_redirects)
  File "/Users/airhao3/miniconda3/envs/bot/lib/python3.10/site-packages/httpx/_client.py", line 1661, in send
    response = await self._send_handling_auth(
  File "/Users/airhao3/miniconda3/envs/bot/lib/python3.10/site-packages/httpx/_client.py", line 1689, in _send_handling_auth
    response = await self._send_handling_redirects(
  File "/Users/airhao3/miniconda3/envs/bot/lib/python3.10/site-packages/httpx/_client.py", line 1726, in _send_handling_redirects
    response = await self._send_single_request(request)
  File "/Users/airhao3/miniconda3/envs/bot/lib/python3.10/site-packages/httpx/_client.py", line 1763, in _send_single_request
    response = await transport.handle_async_request(request)
  File "/Users/airhao3/miniconda3/envs/bot/lib/python3.10/site-packages/httpx/_transports/default.py", line 372, in handle_async_request
    with map_httpcore_exceptions():
  File "/Users/airhao3/miniconda3/envs/bot/lib/python3.10/contextlib.py", line 153, in __exit__
    self.gen.throw(typ, value, traceback)
  File "/Users/airhao3/miniconda3/envs/bot/lib/python3.10/site-packages/httpx/_transports/default.py", line 86, in map_httpcore_exceptions
    raise mapped_exc(message) from exc
httpx.ConnectTimeout

The above exception was the direct cause of the following exception:

Traceback (most recent call last):
  File "/Users/airhao3/miniconda3/envs/bot/lib/python3.10/site-packages/telegram/ext/_application.py", line 1335, in process_update
    await coroutine
  File "/Users/airhao3/miniconda3/envs/bot/lib/python3.10/site-packages/telegram/ext/_handlers/basehandler.py", line 157, in handle_update
    return await self.callback(update, context)
  File "/Users/airhao3/nextcloud/document/telegram-bot-python/telegram-bot-download-proxy.py", line 109, in download_video
    status_message = await update.message.reply_text("Starting download. Please wait...")
  File "/Users/airhao3/miniconda3/envs/bot/lib/python3.10/site-packages/telegram/_message.py", line 1763, in reply_text
    return await self.get_bot().send_message(
  File "/Users/airhao3/miniconda3/envs/bot/lib/python3.10/site-packages/telegram/ext/_extbot.py", line 2907, in send_message
    return await super().send_message(
  File "/Users/airhao3/miniconda3/envs/bot/lib/python3.10/site-packages/telegram/_bot.py", line 1028, in send_message
    return await self._send_message(
  File "/Users/airhao3/miniconda3/envs/bot/lib/python3.10/site-packages/telegram/ext/_extbot.py", line 610, in _send_message
    result = await super()._send_message(
  File "/Users/airhao3/miniconda3/envs/bot/lib/python3.10/site-packages/telegram/_bot.py", line 744, in _send_message
    result = await self._post(
  File "/Users/airhao3/miniconda3/envs/bot/lib/python3.10/site-packages/telegram/_bot.py", line 622, in _post
    return await self._do_post(
  File "/Users/airhao3/miniconda3/envs/bot/lib/python3.10/site-packages/telegram/ext/_extbot.py", line 355, in _do_post
    return await super()._do_post(
  File "/Users/airhao3/miniconda3/envs/bot/lib/python3.10/site-packages/telegram/_bot.py", line 651, in _do_post
    result = await request.post(
  File "/Users/airhao3/miniconda3/envs/bot/lib/python3.10/site-packages/telegram/request/_baserequest.py", line 200, in post
    result = await self._request_wrapper(
  File "/Users/airhao3/miniconda3/envs/bot/lib/python3.10/site-packages/telegram/request/_baserequest.py", line 342, in _request_wrapper
    raise exc
  File "/Users/airhao3/miniconda3/envs/bot/lib/python3.10/site-packages/telegram/request/_baserequest.py", line 332, in _request_wrapper
    code, payload = await self.do_request(
  File "/Users/airhao3/miniconda3/envs/bot/lib/python3.10/site-packages/telegram/request/_httpxrequest.py", line 293, in do_request
    raise TimedOut from err
telegram.error.TimedOut: Timed out
2024-07-22 15:08:54,898 - __main__ - INFO - Received message from user 2042811943 (None): hi
2024-07-22 15:08:54,899 - __main__ - WARNING - User 2042811943 (None) sent invalid URL: hi
2024-07-22 15:08:59,905 - telegram.ext.Application - ERROR - No error handlers are registered, logging exception.
Traceback (most recent call last):
  File "/Users/airhao3/miniconda3/envs/bot/lib/python3.10/site-packages/httpx/_transports/default.py", line 69, in map_httpcore_exceptions
    yield
  File "/Users/airhao3/miniconda3/envs/bot/lib/python3.10/site-packages/httpx/_transports/default.py", line 373, in handle_async_request
    resp = await self._pool.handle_async_request(req)
  File "/Users/airhao3/miniconda3/envs/bot/lib/python3.10/site-packages/httpcore/_async/connection_pool.py", line 216, in handle_async_request
    raise exc from None
  File "/Users/airhao3/miniconda3/envs/bot/lib/python3.10/site-packages/httpcore/_async/connection_pool.py", line 196, in handle_async_request
    response = await connection.handle_async_request(
  File "/Users/airhao3/miniconda3/envs/bot/lib/python3.10/site-packages/httpcore/_async/socks_proxy.py", line 296, in handle_async_request
    raise exc
  File "/Users/airhao3/miniconda3/envs/bot/lib/python3.10/site-packages/httpcore/_async/socks_proxy.py", line 267, in handle_async_request
    stream = await stream.start_tls(**kwargs)
  File "/Users/airhao3/miniconda3/envs/bot/lib/python3.10/site-packages/httpcore/_backends/anyio.py", line 68, in start_tls
    with map_exceptions(exc_map):
  File "/Users/airhao3/miniconda3/envs/bot/lib/python3.10/contextlib.py", line 153, in __exit__
    self.gen.throw(typ, value, traceback)
  File "/Users/airhao3/miniconda3/envs/bot/lib/python3.10/site-packages/httpcore/_exceptions.py", line 14, in map_exceptions
    raise to_exc(exc) from exc
httpcore.ConnectTimeout

The above exception was the direct cause of the following exception:

Traceback (most recent call last):
  File "/Users/airhao3/miniconda3/envs/bot/lib/python3.10/site-packages/telegram/request/_httpxrequest.py", line 276, in do_request
    res = await self._client.request(
  File "/Users/airhao3/miniconda3/envs/bot/lib/python3.10/site-packages/httpx/_client.py", line 1574, in request
    return await self.send(request, auth=auth, follow_redirects=follow_redirects)
  File "/Users/airhao3/miniconda3/envs/bot/lib/python3.10/site-packages/httpx/_client.py", line 1661, in send
    response = await self._send_handling_auth(
  File "/Users/airhao3/miniconda3/envs/bot/lib/python3.10/site-packages/httpx/_client.py", line 1689, in _send_handling_auth
    response = await self._send_handling_redirects(
  File "/Users/airhao3/miniconda3/envs/bot/lib/python3.10/site-packages/httpx/_client.py", line 1726, in _send_handling_redirects
    response = await self._send_single_request(request)
  File "/Users/airhao3/miniconda3/envs/bot/lib/python3.10/site-packages/httpx/_client.py", line 1763, in _send_single_request
    response = await transport.handle_async_request(request)
  File "/Users/airhao3/miniconda3/envs/bot/lib/python3.10/site-packages/httpx/_transports/default.py", line 372, in handle_async_request
    with map_httpcore_exceptions():
  File "/Users/airhao3/miniconda3/envs/bot/lib/python3.10/contextlib.py", line 153, in __exit__
    self.gen.throw(typ, value, traceback)
  File "/Users/airhao3/miniconda3/envs/bot/lib/python3.10/site-packages/httpx/_transports/default.py", line 86, in map_httpcore_exceptions
    raise mapped_exc(message) from exc
httpx.ConnectTimeout

The above exception was the direct cause of the following exception:

Traceback (most recent call last):
  File "/Users/airhao3/miniconda3/envs/bot/lib/python3.10/site-packages/telegram/ext/_application.py", line 1335, in process_update
    await coroutine
  File "/Users/airhao3/miniconda3/envs/bot/lib/python3.10/site-packages/telegram/ext/_handlers/basehandler.py", line 157, in handle_update
    return await self.callback(update, context)
  File "/Users/airhao3/nextcloud/document/telegram-bot-python/telegram-bot-download-proxy.py", line 130, in download_video
    await update.message.reply_text("This is not a valid URL. Please send a video URL.")
  File "/Users/airhao3/miniconda3/envs/bot/lib/python3.10/site-packages/telegram/_message.py", line 1763, in reply_text
    return await self.get_bot().send_message(
  File "/Users/airhao3/miniconda3/envs/bot/lib/python3.10/site-packages/telegram/ext/_extbot.py", line 2907, in send_message
    return await super().send_message(
  File "/Users/airhao3/miniconda3/envs/bot/lib/python3.10/site-packages/telegram/_bot.py", line 1028, in send_message
    return await self._send_message(
  File "/Users/airhao3/miniconda3/envs/bot/lib/python3.10/site-packages/telegram/ext/_extbot.py", line 610, in _send_message
    result = await super()._send_message(
  File "/Users/airhao3/miniconda3/envs/bot/lib/python3.10/site-packages/telegram/_bot.py", line 744, in _send_message
    result = await self._post(
  File "/Users/airhao3/miniconda3/envs/bot/lib/python3.10/site-packages/telegram/_bot.py", line 622, in _post
    return await self._do_post(
  File "/Users/airhao3/miniconda3/envs/bot/lib/python3.10/site-packages/telegram/ext/_extbot.py", line 355, in _do_post
    return await super()._do_post(
  File "/Users/airhao3/miniconda3/envs/bot/lib/python3.10/site-packages/telegram/_bot.py", line 651, in _do_post
    result = await request.post(
  File "/Users/airhao3/miniconda3/envs/bot/lib/python3.10/site-packages/telegram/request/_baserequest.py", line 200, in post
    result = await self._request_wrapper(
  File "/Users/airhao3/miniconda3/envs/bot/lib/python3.10/site-packages/telegram/request/_baserequest.py", line 342, in _request_wrapper
    raise exc
  File "/Users/airhao3/miniconda3/envs/bot/lib/python3.10/site-packages/telegram/request/_baserequest.py", line 332, in _request_wrapper
    code, payload = await self.do_request(
  File "/Users/airhao3/miniconda3/envs/bot/lib/python3.10/site-packages/telegram/request/_httpxrequest.py", line 293, in do_request
    raise TimedOut from err
telegram.error.TimedOut: Timed out
2024-07-22 15:09:02,025 - httpx - INFO - HTTP Request: POST https://api.telegram.org/bot7064977852:AAGEEutTl0D6gVt-Jgz4aXJ4mxK8mLPdL_E/getUpdates "HTTP/1.1 200 OK"
2024-07-22 15:09:12,277 - httpx - INFO - HTTP Request: POST https://api.telegram.org/bot7064977852:AAGEEutTl0D6gVt-Jgz4aXJ4mxK8mLPdL_E/getUpdates "HTTP/1.1 200 OK"
2024-07-22 15:09:22,534 - httpx - INFO - HTTP Request: POST https://api.telegram.org/bot7064977852:AAGEEutTl0D6gVt-Jgz4aXJ4mxK8mLPdL_E/getUpdates "HTTP/1.1 200 OK"
2024-07-22 15:09:32,781 - httpx - INFO - HTTP Request: POST https://api.telegram.org/bot7064977852:AAGEEutTl0D6gVt-Jgz4aXJ4mxK8mLPdL_E/getUpdates "HTTP/1.1 200 OK"
2024-07-22 15:09:43,030 - httpx - INFO - HTTP Request: POST https://api.telegram.org/bot7064977852:AAGEEutTl0D6gVt-Jgz4aXJ4mxK8mLPdL_E/getUpdates "HTTP/1.1 200 OK"
2024-07-22 15:09:46,145 - httpx - INFO - HTTP Request: POST https://api.telegram.org/bot7064977852:AAGEEutTl0D6gVt-Jgz4aXJ4mxK8mLPdL_E/getUpdates "HTTP/1.1 200 OK"
2024-07-22 15:09:46,147 - __main__ - INFO - Received message from user 2042811943 (None): halo
2024-07-22 15:09:46,148 - __main__ - WARNING - User 2042811943 (None) sent invalid URL: halo
2024-07-22 15:09:51,156 - telegram.ext.Application - ERROR - No error handlers are registered, logging exception.
Traceback (most recent call last):
  File "/Users/airhao3/miniconda3/envs/bot/lib/python3.10/site-packages/httpx/_transports/default.py", line 69, in map_httpcore_exceptions
    yield
  File "/Users/airhao3/miniconda3/envs/bot/lib/python3.10/site-packages/httpx/_transports/default.py", line 373, in handle_async_request
    resp = await self._pool.handle_async_request(req)
  File "/Users/airhao3/miniconda3/envs/bot/lib/python3.10/site-packages/httpcore/_async/connection_pool.py", line 216, in handle_async_request
    raise exc from None
  File "/Users/airhao3/miniconda3/envs/bot/lib/python3.10/site-packages/httpcore/_async/connection_pool.py", line 196, in handle_async_request
    response = await connection.handle_async_request(
  File "/Users/airhao3/miniconda3/envs/bot/lib/python3.10/site-packages/httpcore/_async/socks_proxy.py", line 296, in handle_async_request
    raise exc
  File "/Users/airhao3/miniconda3/envs/bot/lib/python3.10/site-packages/httpcore/_async/socks_proxy.py", line 267, in handle_async_request
    stream = await stream.start_tls(**kwargs)
  File "/Users/airhao3/miniconda3/envs/bot/lib/python3.10/site-packages/httpcore/_backends/anyio.py", line 68, in start_tls
    with map_exceptions(exc_map):
  File "/Users/airhao3/miniconda3/envs/bot/lib/python3.10/contextlib.py", line 153, in __exit__
    self.gen.throw(typ, value, traceback)
  File "/Users/airhao3/miniconda3/envs/bot/lib/python3.10/site-packages/httpcore/_exceptions.py", line 14, in map_exceptions
    raise to_exc(exc) from exc
httpcore.ConnectTimeout

The above exception was the direct cause of the following exception:

Traceback (most recent call last):
  File "/Users/airhao3/miniconda3/envs/bot/lib/python3.10/site-packages/telegram/request/_httpxrequest.py", line 276, in do_request
    res = await self._client.request(
  File "/Users/airhao3/miniconda3/envs/bot/lib/python3.10/site-packages/httpx/_client.py", line 1574, in request
    return await self.send(request, auth=auth, follow_redirects=follow_redirects)
  File "/Users/airhao3/miniconda3/envs/bot/lib/python3.10/site-packages/httpx/_client.py", line 1661, in send
    response = await self._send_handling_auth(
  File "/Users/airhao3/miniconda3/envs/bot/lib/python3.10/site-packages/httpx/_client.py", line 1689, in _send_handling_auth
    response = await self._send_handling_redirects(
  File "/Users/airhao3/miniconda3/envs/bot/lib/python3.10/site-packages/httpx/_client.py", line 1726, in _send_handling_redirects
    response = await self._send_single_request(request)
  File "/Users/airhao3/miniconda3/envs/bot/lib/python3.10/site-packages/httpx/_client.py", line 1763, in _send_single_request
    response = await transport.handle_async_request(request)
  File "/Users/airhao3/miniconda3/envs/bot/lib/python3.10/site-packages/httpx/_transports/default.py", line 372, in handle_async_request
    with map_httpcore_exceptions():
  File "/Users/airhao3/miniconda3/envs/bot/lib/python3.10/contextlib.py", line 153, in __exit__
    self.gen.throw(typ, value, traceback)
  File "/Users/airhao3/miniconda3/envs/bot/lib/python3.10/site-packages/httpx/_transports/default.py", line 86, in map_httpcore_exceptions
    raise mapped_exc(message) from exc
httpx.ConnectTimeout

The above exception was the direct cause of the following exception:

Traceback (most recent call last):
  File "/Users/airhao3/miniconda3/envs/bot/lib/python3.10/site-packages/telegram/ext/_application.py", line 1335, in process_update
    await coroutine
  File "/Users/airhao3/miniconda3/envs/bot/lib/python3.10/site-packages/telegram/ext/_handlers/basehandler.py", line 157, in handle_update
    return await self.callback(update, context)
  File "/Users/airhao3/nextcloud/document/telegram-bot-python/telegram-bot-download-proxy.py", line 130, in download_video
    await update.message.reply_text("This is not a valid URL. Please send a video URL.")
  File "/Users/airhao3/miniconda3/envs/bot/lib/python3.10/site-packages/telegram/_message.py", line 1763, in reply_text
    return await self.get_bot().send_message(
  File "/Users/airhao3/miniconda3/envs/bot/lib/python3.10/site-packages/telegram/ext/_extbot.py", line 2907, in send_message
    return await super().send_message(
  File "/Users/airhao3/miniconda3/envs/bot/lib/python3.10/site-packages/telegram/_bot.py", line 1028, in send_message
    return await self._send_message(
  File "/Users/airhao3/miniconda3/envs/bot/lib/python3.10/site-packages/telegram/ext/_extbot.py", line 610, in _send_message
    result = await super()._send_message(
  File "/Users/airhao3/miniconda3/envs/bot/lib/python3.10/site-packages/telegram/_bot.py", line 744, in _send_message
    result = await self._post(
  File "/Users/airhao3/miniconda3/envs/bot/lib/python3.10/site-packages/telegram/_bot.py", line 622, in _post
    return await self._do_post(
  File "/Users/airhao3/miniconda3/envs/bot/lib/python3.10/site-packages/telegram/ext/_extbot.py", line 355, in _do_post
    return await super()._do_post(
  File "/Users/airhao3/miniconda3/envs/bot/lib/python3.10/site-packages/telegram/_bot.py", line 651, in _do_post
    result = await request.post(
  File "/Users/airhao3/miniconda3/envs/bot/lib/python3.10/site-packages/telegram/request/_baserequest.py", line 200, in post
    result = await self._request_wrapper(
  File "/Users/airhao3/miniconda3/envs/bot/lib/python3.10/site-packages/telegram/request/_baserequest.py", line 342, in _request_wrapper
    raise exc
  File "/Users/airhao3/miniconda3/envs/bot/lib/python3.10/site-packages/telegram/request/_baserequest.py", line 332, in _request_wrapper
    code, payload = await self.do_request(
  File "/Users/airhao3/miniconda3/envs/bot/lib/python3.10/site-packages/telegram/request/_httpxrequest.py", line 293, in do_request
    raise TimedOut from err
telegram.error.TimedOut: Timed out
2024-07-22 15:09:56,893 - httpx - INFO - HTTP Request: POST https://api.telegram.org/bot7064977852:AAGEEutTl0D6gVt-Jgz4aXJ4mxK8mLPdL_E/getUpdates "HTTP/1.1 200 OK"
2024-07-22 15:10:07,137 - httpx - INFO - HTTP Request: POST https://api.telegram.org/bot7064977852:AAGEEutTl0D6gVt-Jgz4aXJ4mxK8mLPdL_E/getUpdates "HTTP/1.1 200 OK"
2024-07-22 15:10:17,419 - httpx - INFO - HTTP Request: POST https://api.telegram.org/bot7064977852:AAGEEutTl0D6gVt-Jgz4aXJ4mxK8mLPdL_E/getUpdates "HTTP/1.1 200 OK"
2024-07-22 15:10:27,676 - httpx - INFO - HTTP Request: POST https://api.telegram.org/bot7064977852:AAGEEutTl0D6gVt-Jgz4aXJ4mxK8mLPdL_E/getUpdates "HTTP/1.1 200 OK"
2024-07-22 15:10:37,925 - httpx - INFO - HTTP Request: POST https://api.telegram.org/bot7064977852:AAGEEutTl0D6gVt-Jgz4aXJ4mxK8mLPdL_E/getUpdates "HTTP/1.1 200 OK"
2024-07-22 15:10:48,170 - httpx - INFO - HTTP Request: POST https://api.telegram.org/bot7064977852:AAGEEutTl0D6gVt-Jgz4aXJ4mxK8mLPdL_E/getUpdates "HTTP/1.1 200 OK"
2024-07-22 15:10:58,428 - httpx - INFO - HTTP Request: POST https://api.telegram.org/bot7064977852:AAGEEutTl0D6gVt-Jgz4aXJ4mxK8mLPdL_E/getUpdates "HTTP/1.1 200 OK"
2024-07-22 15:11:08,678 - httpx - INFO - HTTP Request: POST https://api.telegram.org/bot7064977852:AAGEEutTl0D6gVt-Jgz4aXJ4mxK8mLPdL_E/getUpdates "HTTP/1.1 200 OK"
2024-07-22 15:11:19,081 - httpx - INFO - HTTP Request: POST https://api.telegram.org/bot7064977852:AAGEEutTl0D6gVt-Jgz4aXJ4mxK8mLPdL_E/getUpdates "HTTP/1.1 200 OK"
2024-07-22 15:11:29,337 - httpx - INFO - HTTP Request: POST https://api.telegram.org/bot7064977852:AAGEEutTl0D6gVt-Jgz4aXJ4mxK8mLPdL_E/getUpdates "HTTP/1.1 200 OK"
2024-07-22 15:11:39,596 - httpx - INFO - HTTP Request: POST https://api.telegram.org/bot7064977852:AAGEEutTl0D6gVt-Jgz4aXJ4mxK8mLPdL_E/getUpdates "HTTP/1.1 200 OK"
2024-07-22 15:11:49,849 - httpx - INFO - HTTP Request: POST https://api.telegram.org/bot7064977852:AAGEEutTl0D6gVt-Jgz4aXJ4mxK8mLPdL_E/getUpdates "HTTP/1.1 200 OK"
2024-07-22 15:12:00,152 - httpx - INFO - HTTP Request: POST https://api.telegram.org/bot7064977852:AAGEEutTl0D6gVt-Jgz4aXJ4mxK8mLPdL_E/getUpdates "HTTP/1.1 200 OK"
2024-07-22 15:12:10,411 - httpx - INFO - HTTP Request: POST https://api.telegram.org/bot7064977852:AAGEEutTl0D6gVt-Jgz4aXJ4mxK8mLPdL_E/getUpdates "HTTP/1.1 200 OK"
2024-07-22 15:12:20,669 - httpx - INFO - HTTP Request: POST https://api.telegram.org/bot7064977852:AAGEEutTl0D6gVt-Jgz4aXJ4mxK8mLPdL_E/getUpdates "HTTP/1.1 200 OK"
2024-07-22 15:12:30,920 - httpx - INFO - HTTP Request: POST https://api.telegram.org/bot7064977852:AAGEEutTl0D6gVt-Jgz4aXJ4mxK8mLPdL_E/getUpdates "HTTP/1.1 200 OK"
2024-07-22 15:12:35,049 - __main__ - INFO - Starting the bot
2024-07-22 15:13:00,154 - __main__ - INFO - Starting the bot
2024-07-22 15:13:00,282 - __main__ - INFO - Bot is now polling for updates
2024-07-22 15:13:11,827 - __main__ - INFO - Starting the bot
2024-07-22 15:13:11,951 - __main__ - INFO - Bot is now polling for updates
2024-07-22 15:13:19,797 - __main__ - INFO - Starting the bot
2024-07-22 15:13:19,923 - __main__ - INFO - Bot is now polling for updates
2024-07-22 15:13:23,231 - httpx - INFO - HTTP Request: POST https://api.telegram.org/bot7064977852:AAGEEutTl0D6gVt-Jgz4aXJ4mxK8mLPdL_E/getMe "HTTP/1.1 200 OK"
2024-07-22 15:13:23,644 - httpx - INFO - HTTP Request: POST https://api.telegram.org/bot7064977852:AAGEEutTl0D6gVt-Jgz4aXJ4mxK8mLPdL_E/deleteWebhook "HTTP/1.1 200 OK"
2024-07-22 15:13:23,647 - telegram.ext.Application - INFO - Application started
2024-07-22 15:16:00,925 - httpx - INFO - HTTP Request: POST https://api.telegram.org/bot7064977852:AAGEEutTl0D6gVt-Jgz4aXJ4mxK8mLPdL_E/getUpdates "HTTP/1.1 200 OK"
2024-07-22 15:16:00,929 - __main__ - INFO - Received message from user 2042811943 (None): hi
2024-07-22 15:16:00,930 - __main__ - WARNING - User 2042811943 (None) sent invalid URL: hi
2024-07-22 15:16:05,938 - telegram.ext.Application - ERROR - No error handlers are registered, logging exception.
Traceback (most recent call last):
  File "/Users/airhao3/miniconda3/envs/bot/lib/python3.10/site-packages/httpx/_transports/default.py", line 69, in map_httpcore_exceptions
    yield
  File "/Users/airhao3/miniconda3/envs/bot/lib/python3.10/site-packages/httpx/_transports/default.py", line 373, in handle_async_request
    resp = await self._pool.handle_async_request(req)
  File "/Users/airhao3/miniconda3/envs/bot/lib/python3.10/site-packages/httpcore/_async/connection_pool.py", line 216, in handle_async_request
    raise exc from None
  File "/Users/airhao3/miniconda3/envs/bot/lib/python3.10/site-packages/httpcore/_async/connection_pool.py", line 196, in handle_async_request
    response = await connection.handle_async_request(
  File "/Users/airhao3/miniconda3/envs/bot/lib/python3.10/site-packages/httpcore/_async/socks_proxy.py", line 296, in handle_async_request
    raise exc
  File "/Users/airhao3/miniconda3/envs/bot/lib/python3.10/site-packages/httpcore/_async/socks_proxy.py", line 267, in handle_async_request
    stream = await stream.start_tls(**kwargs)
  File "/Users/airhao3/miniconda3/envs/bot/lib/python3.10/site-packages/httpcore/_backends/anyio.py", line 68, in start_tls
    with map_exceptions(exc_map):
  File "/Users/airhao3/miniconda3/envs/bot/lib/python3.10/contextlib.py", line 153, in __exit__
    self.gen.throw(typ, value, traceback)
  File "/Users/airhao3/miniconda3/envs/bot/lib/python3.10/site-packages/httpcore/_exceptions.py", line 14, in map_exceptions
    raise to_exc(exc) from exc
httpcore.ConnectTimeout

The above exception was the direct cause of the following exception:

Traceback (most recent call last):
  File "/Users/airhao3/miniconda3/envs/bot/lib/python3.10/site-packages/telegram/request/_httpxrequest.py", line 276, in do_request
    res = await self._client.request(
  File "/Users/airhao3/miniconda3/envs/bot/lib/python3.10/site-packages/httpx/_client.py", line 1574, in request
    return await self.send(request, auth=auth, follow_redirects=follow_redirects)
  File "/Users/airhao3/miniconda3/envs/bot/lib/python3.10/site-packages/httpx/_client.py", line 1661, in send
    response = await self._send_handling_auth(
  File "/Users/airhao3/miniconda3/envs/bot/lib/python3.10/site-packages/httpx/_client.py", line 1689, in _send_handling_auth
    response = await self._send_handling_redirects(
  File "/Users/airhao3/miniconda3/envs/bot/lib/python3.10/site-packages/httpx/_client.py", line 1726, in _send_handling_redirects
    response = await self._send_single_request(request)
  File "/Users/airhao3/miniconda3/envs/bot/lib/python3.10/site-packages/httpx/_client.py", line 1763, in _send_single_request
    response = await transport.handle_async_request(request)
  File "/Users/airhao3/miniconda3/envs/bot/lib/python3.10/site-packages/httpx/_transports/default.py", line 372, in handle_async_request
    with map_httpcore_exceptions():
  File "/Users/airhao3/miniconda3/envs/bot/lib/python3.10/contextlib.py", line 153, in __exit__
    self.gen.throw(typ, value, traceback)
  File "/Users/airhao3/miniconda3/envs/bot/lib/python3.10/site-packages/httpx/_transports/default.py", line 86, in map_httpcore_exceptions
    raise mapped_exc(message) from exc
httpx.ConnectTimeout

The above exception was the direct cause of the following exception:

Traceback (most recent call last):
  File "/Users/airhao3/miniconda3/envs/bot/lib/python3.10/site-packages/telegram/ext/_application.py", line 1335, in process_update
    await coroutine
  File "/Users/airhao3/miniconda3/envs/bot/lib/python3.10/site-packages/telegram/ext/_handlers/basehandler.py", line 157, in handle_update
    return await self.callback(update, context)
  File "/Users/airhao3/nextcloud/document/telegram-bot-python/telegram-bot-download-proxy.py", line 130, in download_video
    await update.message.reply_text("This is not a valid URL. Please send a video URL.")
  File "/Users/airhao3/miniconda3/envs/bot/lib/python3.10/site-packages/telegram/_message.py", line 1763, in reply_text
    return await self.get_bot().send_message(
  File "/Users/airhao3/miniconda3/envs/bot/lib/python3.10/site-packages/telegram/ext/_extbot.py", line 2907, in send_message
    return await super().send_message(
  File "/Users/airhao3/miniconda3/envs/bot/lib/python3.10/site-packages/telegram/_bot.py", line 1028, in send_message
    return await self._send_message(
  File "/Users/airhao3/miniconda3/envs/bot/lib/python3.10/site-packages/telegram/ext/_extbot.py", line 610, in _send_message
    result = await super()._send_message(
  File "/Users/airhao3/miniconda3/envs/bot/lib/python3.10/site-packages/telegram/_bot.py", line 744, in _send_message
    result = await self._post(
  File "/Users/airhao3/miniconda3/envs/bot/lib/python3.10/site-packages/telegram/_bot.py", line 622, in _post
    return await self._do_post(
  File "/Users/airhao3/miniconda3/envs/bot/lib/python3.10/site-packages/telegram/ext/_extbot.py", line 355, in _do_post
    return await super()._do_post(
  File "/Users/airhao3/miniconda3/envs/bot/lib/python3.10/site-packages/telegram/_bot.py", line 651, in _do_post
    result = await request.post(
  File "/Users/airhao3/miniconda3/envs/bot/lib/python3.10/site-packages/telegram/request/_baserequest.py", line 200, in post
    result = await self._request_wrapper(
  File "/Users/airhao3/miniconda3/envs/bot/lib/python3.10/site-packages/telegram/request/_baserequest.py", line 342, in _request_wrapper
    raise exc
  File "/Users/airhao3/miniconda3/envs/bot/lib/python3.10/site-packages/telegram/request/_baserequest.py", line 332, in _request_wrapper
    code, payload = await self.do_request(
  File "/Users/airhao3/miniconda3/envs/bot/lib/python3.10/site-packages/telegram/request/_httpxrequest.py", line 293, in do_request
    raise TimedOut from err
telegram.error.TimedOut: Timed out
2024-07-22 15:16:05,968 - __main__ - INFO - User 2042811943 (None) started the bot
2024-07-22 15:16:10,975 - telegram.ext.Application - ERROR - No error handlers are registered, logging exception.
Traceback (most recent call last):
  File "/Users/airhao3/miniconda3/envs/bot/lib/python3.10/site-packages/httpx/_transports/default.py", line 69, in map_httpcore_exceptions
    yield
  File "/Users/airhao3/miniconda3/envs/bot/lib/python3.10/site-packages/httpx/_transports/default.py", line 373, in handle_async_request
    resp = await self._pool.handle_async_request(req)
  File "/Users/airhao3/miniconda3/envs/bot/lib/python3.10/site-packages/httpcore/_async/connection_pool.py", line 216, in handle_async_request
    raise exc from None
  File "/Users/airhao3/miniconda3/envs/bot/lib/python3.10/site-packages/httpcore/_async/connection_pool.py", line 196, in handle_async_request
    response = await connection.handle_async_request(
  File "/Users/airhao3/miniconda3/envs/bot/lib/python3.10/site-packages/httpcore/_async/socks_proxy.py", line 296, in handle_async_request
    raise exc
  File "/Users/airhao3/miniconda3/envs/bot/lib/python3.10/site-packages/httpcore/_async/socks_proxy.py", line 267, in handle_async_request
    stream = await stream.start_tls(**kwargs)
  File "/Users/airhao3/miniconda3/envs/bot/lib/python3.10/site-packages/httpcore/_backends/anyio.py", line 68, in start_tls
    with map_exceptions(exc_map):
  File "/Users/airhao3/miniconda3/envs/bot/lib/python3.10/contextlib.py", line 153, in __exit__
    self.gen.throw(typ, value, traceback)
  File "/Users/airhao3/miniconda3/envs/bot/lib/python3.10/site-packages/httpcore/_exceptions.py", line 14, in map_exceptions
    raise to_exc(exc) from exc
httpcore.ConnectTimeout

The above exception was the direct cause of the following exception:

Traceback (most recent call last):
  File "/Users/airhao3/miniconda3/envs/bot/lib/python3.10/site-packages/telegram/request/_httpxrequest.py", line 276, in do_request
    res = await self._client.request(
  File "/Users/airhao3/miniconda3/envs/bot/lib/python3.10/site-packages/httpx/_client.py", line 1574, in request
    return await self.send(request, auth=auth, follow_redirects=follow_redirects)
  File "/Users/airhao3/miniconda3/envs/bot/lib/python3.10/site-packages/httpx/_client.py", line 1661, in send
    response = await self._send_handling_auth(
  File "/Users/airhao3/miniconda3/envs/bot/lib/python3.10/site-packages/httpx/_client.py", line 1689, in _send_handling_auth
    response = await self._send_handling_redirects(
  File "/Users/airhao3/miniconda3/envs/bot/lib/python3.10/site-packages/httpx/_client.py", line 1726, in _send_handling_redirects
    response = await self._send_single_request(request)
  File "/Users/airhao3/miniconda3/envs/bot/lib/python3.10/site-packages/httpx/_client.py", line 1763, in _send_single_request
    response = await transport.handle_async_request(request)
  File "/Users/airhao3/miniconda3/envs/bot/lib/python3.10/site-packages/httpx/_transports/default.py", line 372, in handle_async_request
    with map_httpcore_exceptions():
  File "/Users/airhao3/miniconda3/envs/bot/lib/python3.10/contextlib.py", line 153, in __exit__
    self.gen.throw(typ, value, traceback)
  File "/Users/airhao3/miniconda3/envs/bot/lib/python3.10/site-packages/httpx/_transports/default.py", line 86, in map_httpcore_exceptions
    raise mapped_exc(message) from exc
httpx.ConnectTimeout

The above exception was the direct cause of the following exception:

Traceback (most recent call last):
  File "/Users/airhao3/miniconda3/envs/bot/lib/python3.10/site-packages/telegram/ext/_application.py", line 1335, in process_update
    await coroutine
  File "/Users/airhao3/miniconda3/envs/bot/lib/python3.10/site-packages/telegram/ext/_handlers/basehandler.py", line 157, in handle_update
    return await self.callback(update, context)
  File "/Users/airhao3/nextcloud/document/telegram-bot-python/telegram-bot-download-proxy.py", line 47, in start
    await update.message.reply_html(
  File "/Users/airhao3/miniconda3/envs/bot/lib/python3.10/site-packages/telegram/_message.py", line 2007, in reply_html
    return await self.get_bot().send_message(
  File "/Users/airhao3/miniconda3/envs/bot/lib/python3.10/site-packages/telegram/ext/_extbot.py", line 2907, in send_message
    return await super().send_message(
  File "/Users/airhao3/miniconda3/envs/bot/lib/python3.10/site-packages/telegram/_bot.py", line 1028, in send_message
    return await self._send_message(
  File "/Users/airhao3/miniconda3/envs/bot/lib/python3.10/site-packages/telegram/ext/_extbot.py", line 610, in _send_message
    result = await super()._send_message(
  File "/Users/airhao3/miniconda3/envs/bot/lib/python3.10/site-packages/telegram/_bot.py", line 744, in _send_message
    result = await self._post(
  File "/Users/airhao3/miniconda3/envs/bot/lib/python3.10/site-packages/telegram/_bot.py", line 622, in _post
    return await self._do_post(
  File "/Users/airhao3/miniconda3/envs/bot/lib/python3.10/site-packages/telegram/ext/_extbot.py", line 355, in _do_post
    return await super()._do_post(
  File "/Users/airhao3/miniconda3/envs/bot/lib/python3.10/site-packages/telegram/_bot.py", line 651, in _do_post
    result = await request.post(
  File "/Users/airhao3/miniconda3/envs/bot/lib/python3.10/site-packages/telegram/request/_baserequest.py", line 200, in post
    result = await self._request_wrapper(
  File "/Users/airhao3/miniconda3/envs/bot/lib/python3.10/site-packages/telegram/request/_baserequest.py", line 342, in _request_wrapper
    raise exc
  File "/Users/airhao3/miniconda3/envs/bot/lib/python3.10/site-packages/telegram/request/_baserequest.py", line 332, in _request_wrapper
    code, payload = await self.do_request(
  File "/Users/airhao3/miniconda3/envs/bot/lib/python3.10/site-packages/telegram/request/_httpxrequest.py", line 293, in do_request
    raise TimedOut from err
telegram.error.TimedOut: Timed out
2024-07-22 15:16:10,979 - __main__ - INFO - User 2042811943 (None) requested help
2024-07-22 15:16:11,186 - httpx - INFO - HTTP Request: POST https://api.telegram.org/bot7064977852:AAGEEutTl0D6gVt-Jgz4aXJ4mxK8mLPdL_E/getUpdates "HTTP/1.1 200 OK"
2024-07-22 15:16:15,983 - telegram.ext.Application - ERROR - No error handlers are registered, logging exception.
Traceback (most recent call last):
  File "/Users/airhao3/miniconda3/envs/bot/lib/python3.10/site-packages/httpx/_transports/default.py", line 69, in map_httpcore_exceptions
    yield
  File "/Users/airhao3/miniconda3/envs/bot/lib/python3.10/site-packages/httpx/_transports/default.py", line 373, in handle_async_request
    resp = await self._pool.handle_async_request(req)
  File "/Users/airhao3/miniconda3/envs/bot/lib/python3.10/site-packages/httpcore/_async/connection_pool.py", line 216, in handle_async_request
    raise exc from None
  File "/Users/airhao3/miniconda3/envs/bot/lib/python3.10/site-packages/httpcore/_async/connection_pool.py", line 196, in handle_async_request
    response = await connection.handle_async_request(
  File "/Users/airhao3/miniconda3/envs/bot/lib/python3.10/site-packages/httpcore/_async/socks_proxy.py", line 296, in handle_async_request
    raise exc
  File "/Users/airhao3/miniconda3/envs/bot/lib/python3.10/site-packages/httpcore/_async/socks_proxy.py", line 267, in handle_async_request
    stream = await stream.start_tls(**kwargs)
  File "/Users/airhao3/miniconda3/envs/bot/lib/python3.10/site-packages/httpcore/_backends/anyio.py", line 68, in start_tls
    with map_exceptions(exc_map):
  File "/Users/airhao3/miniconda3/envs/bot/lib/python3.10/contextlib.py", line 153, in __exit__
    self.gen.throw(typ, value, traceback)
  File "/Users/airhao3/miniconda3/envs/bot/lib/python3.10/site-packages/httpcore/_exceptions.py", line 14, in map_exceptions
    raise to_exc(exc) from exc
httpcore.ConnectTimeout

The above exception was the direct cause of the following exception:

Traceback (most recent call last):
  File "/Users/airhao3/miniconda3/envs/bot/lib/python3.10/site-packages/telegram/request/_httpxrequest.py", line 276, in do_request
    res = await self._client.request(
  File "/Users/airhao3/miniconda3/envs/bot/lib/python3.10/site-packages/httpx/_client.py", line 1574, in request
    return await self.send(request, auth=auth, follow_redirects=follow_redirects)
  File "/Users/airhao3/miniconda3/envs/bot/lib/python3.10/site-packages/httpx/_client.py", line 1661, in send
    response = await self._send_handling_auth(
  File "/Users/airhao3/miniconda3/envs/bot/lib/python3.10/site-packages/httpx/_client.py", line 1689, in _send_handling_auth
    response = await self._send_handling_redirects(
  File "/Users/airhao3/miniconda3/envs/bot/lib/python3.10/site-packages/httpx/_client.py", line 1726, in _send_handling_redirects
    response = await self._send_single_request(request)
  File "/Users/airhao3/miniconda3/envs/bot/lib/python3.10/site-packages/httpx/_client.py", line 1763, in _send_single_request
    response = await transport.handle_async_request(request)
  File "/Users/airhao3/miniconda3/envs/bot/lib/python3.10/site-packages/httpx/_transports/default.py", line 372, in handle_async_request
    with map_httpcore_exceptions():
  File "/Users/airhao3/miniconda3/envs/bot/lib/python3.10/contextlib.py", line 153, in __exit__
    self.gen.throw(typ, value, traceback)
  File "/Users/airhao3/miniconda3/envs/bot/lib/python3.10/site-packages/httpx/_transports/default.py", line 86, in map_httpcore_exceptions
    raise mapped_exc(message) from exc
httpx.ConnectTimeout

The above exception was the direct cause of the following exception:

Traceback (most recent call last):
  File "/Users/airhao3/miniconda3/envs/bot/lib/python3.10/site-packages/telegram/ext/_application.py", line 1335, in process_update
    await coroutine
  File "/Users/airhao3/miniconda3/envs/bot/lib/python3.10/site-packages/telegram/ext/_handlers/basehandler.py", line 157, in handle_update
    return await self.callback(update, context)
  File "/Users/airhao3/nextcloud/document/telegram-bot-python/telegram-bot-download-proxy.py", line 55, in help_command
    await update.message.reply_text("Send me a video URL, and I'll download it for you!")
  File "/Users/airhao3/miniconda3/envs/bot/lib/python3.10/site-packages/telegram/_message.py", line 1763, in reply_text
    return await self.get_bot().send_message(
  File "/Users/airhao3/miniconda3/envs/bot/lib/python3.10/site-packages/telegram/ext/_extbot.py", line 2907, in send_message
    return await super().send_message(
  File "/Users/airhao3/miniconda3/envs/bot/lib/python3.10/site-packages/telegram/_bot.py", line 1028, in send_message
    return await self._send_message(
  File "/Users/airhao3/miniconda3/envs/bot/lib/python3.10/site-packages/telegram/ext/_extbot.py", line 610, in _send_message
    result = await super()._send_message(
  File "/Users/airhao3/miniconda3/envs/bot/lib/python3.10/site-packages/telegram/_bot.py", line 744, in _send_message
    result = await self._post(
  File "/Users/airhao3/miniconda3/envs/bot/lib/python3.10/site-packages/telegram/_bot.py", line 622, in _post
    return await self._do_post(
  File "/Users/airhao3/miniconda3/envs/bot/lib/python3.10/site-packages/telegram/ext/_extbot.py", line 355, in _do_post
    return await super()._do_post(
  File "/Users/airhao3/miniconda3/envs/bot/lib/python3.10/site-packages/telegram/_bot.py", line 651, in _do_post
    result = await request.post(
  File "/Users/airhao3/miniconda3/envs/bot/lib/python3.10/site-packages/telegram/request/_baserequest.py", line 200, in post
    result = await self._request_wrapper(
  File "/Users/airhao3/miniconda3/envs/bot/lib/python3.10/site-packages/telegram/request/_baserequest.py", line 342, in _request_wrapper
    raise exc
  File "/Users/airhao3/miniconda3/envs/bot/lib/python3.10/site-packages/telegram/request/_baserequest.py", line 332, in _request_wrapper
    code, payload = await self.do_request(
  File "/Users/airhao3/miniconda3/envs/bot/lib/python3.10/site-packages/telegram/request/_httpxrequest.py", line 293, in do_request
    raise TimedOut from err
telegram.error.TimedOut: Timed out
2024-07-22 15:16:15,986 - __main__ - INFO - Received message from user 2042811943 (None): help
2024-07-22 15:16:15,986 - __main__ - WARNING - User 2042811943 (None) sent invalid URL: help
2024-07-22 15:16:20,992 - telegram.ext.Application - ERROR - No error handlers are registered, logging exception.
Traceback (most recent call last):
  File "/Users/airhao3/miniconda3/envs/bot/lib/python3.10/site-packages/httpx/_transports/default.py", line 69, in map_httpcore_exceptions
    yield
  File "/Users/airhao3/miniconda3/envs/bot/lib/python3.10/site-packages/httpx/_transports/default.py", line 373, in handle_async_request
    resp = await self._pool.handle_async_request(req)
  File "/Users/airhao3/miniconda3/envs/bot/lib/python3.10/site-packages/httpcore/_async/connection_pool.py", line 216, in handle_async_request
    raise exc from None
  File "/Users/airhao3/miniconda3/envs/bot/lib/python3.10/site-packages/httpcore/_async/connection_pool.py", line 196, in handle_async_request
    response = await connection.handle_async_request(
  File "/Users/airhao3/miniconda3/envs/bot/lib/python3.10/site-packages/httpcore/_async/socks_proxy.py", line 296, in handle_async_request
    raise exc
  File "/Users/airhao3/miniconda3/envs/bot/lib/python3.10/site-packages/httpcore/_async/socks_proxy.py", line 267, in handle_async_request
    stream = await stream.start_tls(**kwargs)
  File "/Users/airhao3/miniconda3/envs/bot/lib/python3.10/site-packages/httpcore/_backends/anyio.py", line 68, in start_tls
    with map_exceptions(exc_map):
  File "/Users/airhao3/miniconda3/envs/bot/lib/python3.10/contextlib.py", line 153, in __exit__
    self.gen.throw(typ, value, traceback)
  File "/Users/airhao3/miniconda3/envs/bot/lib/python3.10/site-packages/httpcore/_exceptions.py", line 14, in map_exceptions
    raise to_exc(exc) from exc
httpcore.ConnectTimeout

The above exception was the direct cause of the following exception:

Traceback (most recent call last):
  File "/Users/airhao3/miniconda3/envs/bot/lib/python3.10/site-packages/telegram/request/_httpxrequest.py", line 276, in do_request
    res = await self._client.request(
  File "/Users/airhao3/miniconda3/envs/bot/lib/python3.10/site-packages/httpx/_client.py", line 1574, in request
    return await self.send(request, auth=auth, follow_redirects=follow_redirects)
  File "/Users/airhao3/miniconda3/envs/bot/lib/python3.10/site-packages/httpx/_client.py", line 1661, in send
    response = await self._send_handling_auth(
  File "/Users/airhao3/miniconda3/envs/bot/lib/python3.10/site-packages/httpx/_client.py", line 1689, in _send_handling_auth
    response = await self._send_handling_redirects(
  File "/Users/airhao3/miniconda3/envs/bot/lib/python3.10/site-packages/httpx/_client.py", line 1726, in _send_handling_redirects
    response = await self._send_single_request(request)
  File "/Users/airhao3/miniconda3/envs/bot/lib/python3.10/site-packages/httpx/_client.py", line 1763, in _send_single_request
    response = await transport.handle_async_request(request)
  File "/Users/airhao3/miniconda3/envs/bot/lib/python3.10/site-packages/httpx/_transports/default.py", line 372, in handle_async_request
    with map_httpcore_exceptions():
  File "/Users/airhao3/miniconda3/envs/bot/lib/python3.10/contextlib.py", line 153, in __exit__
    self.gen.throw(typ, value, traceback)
  File "/Users/airhao3/miniconda3/envs/bot/lib/python3.10/site-packages/httpx/_transports/default.py", line 86, in map_httpcore_exceptions
    raise mapped_exc(message) from exc
httpx.ConnectTimeout

The above exception was the direct cause of the following exception:

Traceback (most recent call last):
  File "/Users/airhao3/miniconda3/envs/bot/lib/python3.10/site-packages/telegram/ext/_application.py", line 1335, in process_update
    await coroutine
  File "/Users/airhao3/miniconda3/envs/bot/lib/python3.10/site-packages/telegram/ext/_handlers/basehandler.py", line 157, in handle_update
    return await self.callback(update, context)
  File "/Users/airhao3/nextcloud/document/telegram-bot-python/telegram-bot-download-proxy.py", line 130, in download_video
    await update.message.reply_text("This is not a valid URL. Please send a video URL.")
  File "/Users/airhao3/miniconda3/envs/bot/lib/python3.10/site-packages/telegram/_message.py", line 1763, in reply_text
    return await self.get_bot().send_message(
  File "/Users/airhao3/miniconda3/envs/bot/lib/python3.10/site-packages/telegram/ext/_extbot.py", line 2907, in send_message
    return await super().send_message(
  File "/Users/airhao3/miniconda3/envs/bot/lib/python3.10/site-packages/telegram/_bot.py", line 1028, in send_message
    return await self._send_message(
  File "/Users/airhao3/miniconda3/envs/bot/lib/python3.10/site-packages/telegram/ext/_extbot.py", line 610, in _send_message
    result = await super()._send_message(
  File "/Users/airhao3/miniconda3/envs/bot/lib/python3.10/site-packages/telegram/_bot.py", line 744, in _send_message
    result = await self._post(
  File "/Users/airhao3/miniconda3/envs/bot/lib/python3.10/site-packages/telegram/_bot.py", line 622, in _post
    return await self._do_post(
  File "/Users/airhao3/miniconda3/envs/bot/lib/python3.10/site-packages/telegram/ext/_extbot.py", line 355, in _do_post
    return await super()._do_post(
  File "/Users/airhao3/miniconda3/envs/bot/lib/python3.10/site-packages/telegram/_bot.py", line 651, in _do_post
    result = await request.post(
  File "/Users/airhao3/miniconda3/envs/bot/lib/python3.10/site-packages/telegram/request/_baserequest.py", line 200, in post
    result = await self._request_wrapper(
  File "/Users/airhao3/miniconda3/envs/bot/lib/python3.10/site-packages/telegram/request/_baserequest.py", line 342, in _request_wrapper
    raise exc
  File "/Users/airhao3/miniconda3/envs/bot/lib/python3.10/site-packages/telegram/request/_baserequest.py", line 332, in _request_wrapper
    code, payload = await self.do_request(
  File "/Users/airhao3/miniconda3/envs/bot/lib/python3.10/site-packages/telegram/request/_httpxrequest.py", line 293, in do_request
    raise TimedOut from err
telegram.error.TimedOut: Timed out
2024-07-22 15:16:21,463 - httpx - INFO - HTTP Request: POST https://api.telegram.org/bot7064977852:AAGEEutTl0D6gVt-Jgz4aXJ4mxK8mLPdL_E/getUpdates "HTTP/1.1 200 OK"
2024-07-22 15:16:31,718 - httpx - INFO - HTTP Request: POST https://api.telegram.org/bot7064977852:AAGEEutTl0D6gVt-Jgz4aXJ4mxK8mLPdL_E/getUpdates "HTTP/1.1 200 OK"
2024-07-22 15:16:42,091 - httpx - INFO - HTTP Request: POST https://api.telegram.org/bot7064977852:AAGEEutTl0D6gVt-Jgz4aXJ4mxK8mLPdL_E/getUpdates "HTTP/1.1 200 OK"
2024-07-22 15:16:52,366 - httpx - INFO - HTTP Request: POST https://api.telegram.org/bot7064977852:AAGEEutTl0D6gVt-Jgz4aXJ4mxK8mLPdL_E/getUpdates "HTTP/1.1 200 OK"
2024-07-22 15:17:02,628 - httpx - INFO - HTTP Request: POST https://api.telegram.org/bot7064977852:AAGEEutTl0D6gVt-Jgz4aXJ4mxK8mLPdL_E/getUpdates "HTTP/1.1 200 OK"
2024-07-22 15:17:12,906 - httpx - INFO - HTTP Request: POST https://api.telegram.org/bot7064977852:AAGEEutTl0D6gVt-Jgz4aXJ4mxK8mLPdL_E/getUpdates "HTTP/1.1 200 OK"
2024-07-22 15:17:23,204 - httpx - INFO - HTTP Request: POST https://api.telegram.org/bot7064977852:AAGEEutTl0D6gVt-Jgz4aXJ4mxK8mLPdL_E/getUpdates "HTTP/1.1 200 OK"
2024-07-22 15:17:33,516 - httpx - INFO - HTTP Request: POST https://api.telegram.org/bot7064977852:AAGEEutTl0D6gVt-Jgz4aXJ4mxK8mLPdL_E/getUpdates "HTTP/1.1 200 OK"
2024-07-22 15:17:43,770 - httpx - INFO - HTTP Request: POST https://api.telegram.org/bot7064977852:AAGEEutTl0D6gVt-Jgz4aXJ4mxK8mLPdL_E/getUpdates "HTTP/1.1 200 OK"
2024-07-22 15:17:54,036 - httpx - INFO - HTTP Request: POST https://api.telegram.org/bot7064977852:AAGEEutTl0D6gVt-Jgz4aXJ4mxK8mLPdL_E/getUpdates "HTTP/1.1 200 OK"
2024-07-22 15:17:57,678 - httpx - INFO - HTTP Request: POST https://api.telegram.org/bot7064977852:AAGEEutTl0D6gVt-Jgz4aXJ4mxK8mLPdL_E/getUpdates "HTTP/1.1 200 OK"
2024-07-22 15:17:57,680 - __main__ - INFO - Received message from user 2042811943 (None): hi
2024-07-22 15:17:57,680 - __main__ - WARNING - User 2042811943 (None) sent invalid URL: hi
2024-07-22 15:18:02,698 - telegram.ext.Application - ERROR - No error handlers are registered, logging exception.
Traceback (most recent call last):
  File "/Users/airhao3/miniconda3/envs/bot/lib/python3.10/site-packages/httpx/_transports/default.py", line 69, in map_httpcore_exceptions
    yield
  File "/Users/airhao3/miniconda3/envs/bot/lib/python3.10/site-packages/httpx/_transports/default.py", line 373, in handle_async_request
    resp = await self._pool.handle_async_request(req)
  File "/Users/airhao3/miniconda3/envs/bot/lib/python3.10/site-packages/httpcore/_async/connection_pool.py", line 216, in handle_async_request
    raise exc from None
  File "/Users/airhao3/miniconda3/envs/bot/lib/python3.10/site-packages/httpcore/_async/connection_pool.py", line 196, in handle_async_request
    response = await connection.handle_async_request(
  File "/Users/airhao3/miniconda3/envs/bot/lib/python3.10/site-packages/httpcore/_async/socks_proxy.py", line 296, in handle_async_request
    raise exc
  File "/Users/airhao3/miniconda3/envs/bot/lib/python3.10/site-packages/httpcore/_async/socks_proxy.py", line 267, in handle_async_request
    stream = await stream.start_tls(**kwargs)
  File "/Users/airhao3/miniconda3/envs/bot/lib/python3.10/site-packages/httpcore/_backends/anyio.py", line 68, in start_tls
    with map_exceptions(exc_map):
  File "/Users/airhao3/miniconda3/envs/bot/lib/python3.10/contextlib.py", line 153, in __exit__
    self.gen.throw(typ, value, traceback)
  File "/Users/airhao3/miniconda3/envs/bot/lib/python3.10/site-packages/httpcore/_exceptions.py", line 14, in map_exceptions
    raise to_exc(exc) from exc
httpcore.ConnectTimeout

The above exception was the direct cause of the following exception:

Traceback (most recent call last):
  File "/Users/airhao3/miniconda3/envs/bot/lib/python3.10/site-packages/telegram/request/_httpxrequest.py", line 276, in do_request
    res = await self._client.request(
  File "/Users/airhao3/miniconda3/envs/bot/lib/python3.10/site-packages/httpx/_client.py", line 1574, in request
    return await self.send(request, auth=auth, follow_redirects=follow_redirects)
  File "/Users/airhao3/miniconda3/envs/bot/lib/python3.10/site-packages/httpx/_client.py", line 1661, in send
    response = await self._send_handling_auth(
  File "/Users/airhao3/miniconda3/envs/bot/lib/python3.10/site-packages/httpx/_client.py", line 1689, in _send_handling_auth
    response = await self._send_handling_redirects(
  File "/Users/airhao3/miniconda3/envs/bot/lib/python3.10/site-packages/httpx/_client.py", line 1726, in _send_handling_redirects
    response = await self._send_single_request(request)
  File "/Users/airhao3/miniconda3/envs/bot/lib/python3.10/site-packages/httpx/_client.py", line 1763, in _send_single_request
    response = await transport.handle_async_request(request)
  File "/Users/airhao3/miniconda3/envs/bot/lib/python3.10/site-packages/httpx/_transports/default.py", line 372, in handle_async_request
    with map_httpcore_exceptions():
  File "/Users/airhao3/miniconda3/envs/bot/lib/python3.10/contextlib.py", line 153, in __exit__
    self.gen.throw(typ, value, traceback)
  File "/Users/airhao3/miniconda3/envs/bot/lib/python3.10/site-packages/httpx/_transports/default.py", line 86, in map_httpcore_exceptions
    raise mapped_exc(message) from exc
httpx.ConnectTimeout

The above exception was the direct cause of the following exception:

Traceback (most recent call last):
  File "/Users/airhao3/miniconda3/envs/bot/lib/python3.10/site-packages/telegram/ext/_application.py", line 1335, in process_update
    await coroutine
  File "/Users/airhao3/miniconda3/envs/bot/lib/python3.10/site-packages/telegram/ext/_handlers/basehandler.py", line 157, in handle_update
    return await self.callback(update, context)
  File "/Users/airhao3/nextcloud/document/telegram-bot-python/telegram-bot-download-proxy.py", line 130, in download_video
    await update.message.reply_text("This is not a valid URL. Please send a video URL.")
  File "/Users/airhao3/miniconda3/envs/bot/lib/python3.10/site-packages/telegram/_message.py", line 1763, in reply_text
    return await self.get_bot().send_message(
  File "/Users/airhao3/miniconda3/envs/bot/lib/python3.10/site-packages/telegram/ext/_extbot.py", line 2907, in send_message
    return await super().send_message(
  File "/Users/airhao3/miniconda3/envs/bot/lib/python3.10/site-packages/telegram/_bot.py", line 1028, in send_message
    return await self._send_message(
  File "/Users/airhao3/miniconda3/envs/bot/lib/python3.10/site-packages/telegram/ext/_extbot.py", line 610, in _send_message
    result = await super()._send_message(
  File "/Users/airhao3/miniconda3/envs/bot/lib/python3.10/site-packages/telegram/_bot.py", line 744, in _send_message
    result = await self._post(
  File "/Users/airhao3/miniconda3/envs/bot/lib/python3.10/site-packages/telegram/_bot.py", line 622, in _post
    return await self._do_post(
  File "/Users/airhao3/miniconda3/envs/bot/lib/python3.10/site-packages/telegram/ext/_extbot.py", line 355, in _do_post
    return await super()._do_post(
  File "/Users/airhao3/miniconda3/envs/bot/lib/python3.10/site-packages/telegram/_bot.py", line 651, in _do_post
    result = await request.post(
  File "/Users/airhao3/miniconda3/envs/bot/lib/python3.10/site-packages/telegram/request/_baserequest.py", line 200, in post
    result = await self._request_wrapper(
  File "/Users/airhao3/miniconda3/envs/bot/lib/python3.10/site-packages/telegram/request/_baserequest.py", line 342, in _request_wrapper
    raise exc
  File "/Users/airhao3/miniconda3/envs/bot/lib/python3.10/site-packages/telegram/request/_baserequest.py", line 332, in _request_wrapper
    code, payload = await self.do_request(
  File "/Users/airhao3/miniconda3/envs/bot/lib/python3.10/site-packages/telegram/request/_httpxrequest.py", line 293, in do_request
    raise TimedOut from err
telegram.error.TimedOut: Timed out
2024-07-22 15:18:07,929 - httpx - INFO - HTTP Request: POST https://api.telegram.org/bot7064977852:AAGEEutTl0D6gVt-Jgz4aXJ4mxK8mLPdL_E/getUpdates "HTTP/1.1 200 OK"
2024-07-22 15:18:12,767 - httpx - INFO - HTTP Request: POST https://api.telegram.org/bot7064977852:AAGEEutTl0D6gVt-Jgz4aXJ4mxK8mLPdL_E/getUpdates "HTTP/1.1 200 OK"
2024-07-22 15:18:12,770 - __main__ - INFO - Received message from user 2042811943 (None): https://youtube.com/shorts/cnGJ86yf0cM?si=RlZ0yX6baDDHjUJF
2024-07-22 15:18:17,784 - telegram.ext.Application - ERROR - No error handlers are registered, logging exception.
Traceback (most recent call last):
  File "/Users/airhao3/miniconda3/envs/bot/lib/python3.10/site-packages/httpx/_transports/default.py", line 69, in map_httpcore_exceptions
    yield
  File "/Users/airhao3/miniconda3/envs/bot/lib/python3.10/site-packages/httpx/_transports/default.py", line 373, in handle_async_request
    resp = await self._pool.handle_async_request(req)
  File "/Users/airhao3/miniconda3/envs/bot/lib/python3.10/site-packages/httpcore/_async/connection_pool.py", line 216, in handle_async_request
    raise exc from None
  File "/Users/airhao3/miniconda3/envs/bot/lib/python3.10/site-packages/httpcore/_async/connection_pool.py", line 196, in handle_async_request
    response = await connection.handle_async_request(
  File "/Users/airhao3/miniconda3/envs/bot/lib/python3.10/site-packages/httpcore/_async/socks_proxy.py", line 296, in handle_async_request
    raise exc
  File "/Users/airhao3/miniconda3/envs/bot/lib/python3.10/site-packages/httpcore/_async/socks_proxy.py", line 267, in handle_async_request
    stream = await stream.start_tls(**kwargs)
  File "/Users/airhao3/miniconda3/envs/bot/lib/python3.10/site-packages/httpcore/_backends/anyio.py", line 68, in start_tls
    with map_exceptions(exc_map):
  File "/Users/airhao3/miniconda3/envs/bot/lib/python3.10/contextlib.py", line 153, in __exit__
    self.gen.throw(typ, value, traceback)
  File "/Users/airhao3/miniconda3/envs/bot/lib/python3.10/site-packages/httpcore/_exceptions.py", line 14, in map_exceptions
    raise to_exc(exc) from exc
httpcore.ConnectTimeout

The above exception was the direct cause of the following exception:

Traceback (most recent call last):
  File "/Users/airhao3/miniconda3/envs/bot/lib/python3.10/site-packages/telegram/request/_httpxrequest.py", line 276, in do_request
    res = await self._client.request(
  File "/Users/airhao3/miniconda3/envs/bot/lib/python3.10/site-packages/httpx/_client.py", line 1574, in request
    return await self.send(request, auth=auth, follow_redirects=follow_redirects)
  File "/Users/airhao3/miniconda3/envs/bot/lib/python3.10/site-packages/httpx/_client.py", line 1661, in send
    response = await self._send_handling_auth(
  File "/Users/airhao3/miniconda3/envs/bot/lib/python3.10/site-packages/httpx/_client.py", line 1689, in _send_handling_auth
    response = await self._send_handling_redirects(
  File "/Users/airhao3/miniconda3/envs/bot/lib/python3.10/site-packages/httpx/_client.py", line 1726, in _send_handling_redirects
    response = await self._send_single_request(request)
  File "/Users/airhao3/miniconda3/envs/bot/lib/python3.10/site-packages/httpx/_client.py", line 1763, in _send_single_request
    response = await transport.handle_async_request(request)
  File "/Users/airhao3/miniconda3/envs/bot/lib/python3.10/site-packages/httpx/_transports/default.py", line 372, in handle_async_request
    with map_httpcore_exceptions():
  File "/Users/airhao3/miniconda3/envs/bot/lib/python3.10/contextlib.py", line 153, in __exit__
    self.gen.throw(typ, value, traceback)
  File "/Users/airhao3/miniconda3/envs/bot/lib/python3.10/site-packages/httpx/_transports/default.py", line 86, in map_httpcore_exceptions
    raise mapped_exc(message) from exc
httpx.ConnectTimeout

The above exception was the direct cause of the following exception:

Traceback (most recent call last):
  File "/Users/airhao3/miniconda3/envs/bot/lib/python3.10/site-packages/telegram/ext/_application.py", line 1335, in process_update
    await coroutine
  File "/Users/airhao3/miniconda3/envs/bot/lib/python3.10/site-packages/telegram/ext/_handlers/basehandler.py", line 157, in handle_update
    return await self.callback(update, context)
  File "/Users/airhao3/nextcloud/document/telegram-bot-python/telegram-bot-download-proxy.py", line 109, in download_video
    status_message = await update.message.reply_text("Starting download. Please wait...")
  File "/Users/airhao3/miniconda3/envs/bot/lib/python3.10/site-packages/telegram/_message.py", line 1763, in reply_text
    return await self.get_bot().send_message(
  File "/Users/airhao3/miniconda3/envs/bot/lib/python3.10/site-packages/telegram/ext/_extbot.py", line 2907, in send_message
    return await super().send_message(
  File "/Users/airhao3/miniconda3/envs/bot/lib/python3.10/site-packages/telegram/_bot.py", line 1028, in send_message
    return await self._send_message(
  File "/Users/airhao3/miniconda3/envs/bot/lib/python3.10/site-packages/telegram/ext/_extbot.py", line 610, in _send_message
    result = await super()._send_message(
  File "/Users/airhao3/miniconda3/envs/bot/lib/python3.10/site-packages/telegram/_bot.py", line 744, in _send_message
    result = await self._post(
  File "/Users/airhao3/miniconda3/envs/bot/lib/python3.10/site-packages/telegram/_bot.py", line 622, in _post
    return await self._do_post(
  File "/Users/airhao3/miniconda3/envs/bot/lib/python3.10/site-packages/telegram/ext/_extbot.py", line 355, in _do_post
    return await super()._do_post(
  File "/Users/airhao3/miniconda3/envs/bot/lib/python3.10/site-packages/telegram/_bot.py", line 651, in _do_post
    result = await request.post(
  File "/Users/airhao3/miniconda3/envs/bot/lib/python3.10/site-packages/telegram/request/_baserequest.py", line 200, in post
    result = await self._request_wrapper(
  File "/Users/airhao3/miniconda3/envs/bot/lib/python3.10/site-packages/telegram/request/_baserequest.py", line 342, in _request_wrapper
    raise exc
  File "/Users/airhao3/miniconda3/envs/bot/lib/python3.10/site-packages/telegram/request/_baserequest.py", line 332, in _request_wrapper
    code, payload = await self.do_request(
  File "/Users/airhao3/miniconda3/envs/bot/lib/python3.10/site-packages/telegram/request/_httpxrequest.py", line 293, in do_request
    raise TimedOut from err
telegram.error.TimedOut: Timed out
2024-07-22 15:18:23,032 - httpx - INFO - HTTP Request: POST https://api.telegram.org/bot7064977852:AAGEEutTl0D6gVt-Jgz4aXJ4mxK8mLPdL_E/getUpdates "HTTP/1.1 200 OK"
2024-07-22 15:18:33,323 - httpx - INFO - HTTP Request: POST https://api.telegram.org/bot7064977852:AAGEEutTl0D6gVt-Jgz4aXJ4mxK8mLPdL_E/getUpdates "HTTP/1.1 200 OK"
2024-07-22 15:18:43,680 - httpx - INFO - HTTP Request: POST https://api.telegram.org/bot7064977852:AAGEEutTl0D6gVt-Jgz4aXJ4mxK8mLPdL_E/getUpdates "HTTP/1.1 200 OK"
2024-07-22 15:18:53,950 - httpx - INFO - HTTP Request: POST https://api.telegram.org/bot7064977852:AAGEEutTl0D6gVt-Jgz4aXJ4mxK8mLPdL_E/getUpdates "HTTP/1.1 200 OK"
2024-07-22 15:19:04,231 - httpx - INFO - HTTP Request: POST https://api.telegram.org/bot7064977852:AAGEEutTl0D6gVt-Jgz4aXJ4mxK8mLPdL_E/getUpdates "HTTP/1.1 200 OK"
2024-07-22 15:19:14,491 - httpx - INFO - HTTP Request: POST https://api.telegram.org/bot7064977852:AAGEEutTl0D6gVt-Jgz4aXJ4mxK8mLPdL_E/getUpdates "HTTP/1.1 200 OK"
2024-07-22 15:19:24,753 - httpx - INFO - HTTP Request: POST https://api.telegram.org/bot7064977852:AAGEEutTl0D6gVt-Jgz4aXJ4mxK8mLPdL_E/getUpdates "HTTP/1.1 200 OK"
2024-07-22 15:19:35,006 - httpx - INFO - HTTP Request: POST https://api.telegram.org/bot7064977852:AAGEEutTl0D6gVt-Jgz4aXJ4mxK8mLPdL_E/getUpdates "HTTP/1.1 200 OK"
2024-07-22 15:19:40,873 - httpx - INFO - HTTP Request: POST https://api.telegram.org/bot7064977852:AAGEEutTl0D6gVt-Jgz4aXJ4mxK8mLPdL_E/getUpdates "HTTP/1.1 200 OK"
2024-07-22 15:19:40,875 - __main__ - INFO - Received message from user 2042811943 (None): hihi
2024-07-22 15:19:40,876 - __main__ - WARNING - User 2042811943 (None) sent invalid URL: hihi
2024-07-22 15:19:45,883 - telegram.ext.Application - ERROR - No error handlers are registered, logging exception.
Traceback (most recent call last):
  File "/Users/airhao3/miniconda3/envs/bot/lib/python3.10/site-packages/httpx/_transports/default.py", line 69, in map_httpcore_exceptions
    yield
  File "/Users/airhao3/miniconda3/envs/bot/lib/python3.10/site-packages/httpx/_transports/default.py", line 373, in handle_async_request
    resp = await self._pool.handle_async_request(req)
  File "/Users/airhao3/miniconda3/envs/bot/lib/python3.10/site-packages/httpcore/_async/connection_pool.py", line 216, in handle_async_request
    raise exc from None
  File "/Users/airhao3/miniconda3/envs/bot/lib/python3.10/site-packages/httpcore/_async/connection_pool.py", line 196, in handle_async_request
    response = await connection.handle_async_request(
  File "/Users/airhao3/miniconda3/envs/bot/lib/python3.10/site-packages/httpcore/_async/socks_proxy.py", line 296, in handle_async_request
    raise exc
  File "/Users/airhao3/miniconda3/envs/bot/lib/python3.10/site-packages/httpcore/_async/socks_proxy.py", line 267, in handle_async_request
    stream = await stream.start_tls(**kwargs)
  File "/Users/airhao3/miniconda3/envs/bot/lib/python3.10/site-packages/httpcore/_backends/anyio.py", line 68, in start_tls
    with map_exceptions(exc_map):
  File "/Users/airhao3/miniconda3/envs/bot/lib/python3.10/contextlib.py", line 153, in __exit__
    self.gen.throw(typ, value, traceback)
  File "/Users/airhao3/miniconda3/envs/bot/lib/python3.10/site-packages/httpcore/_exceptions.py", line 14, in map_exceptions
    raise to_exc(exc) from exc
httpcore.ConnectTimeout

The above exception was the direct cause of the following exception:

Traceback (most recent call last):
  File "/Users/airhao3/miniconda3/envs/bot/lib/python3.10/site-packages/telegram/request/_httpxrequest.py", line 276, in do_request
    res = await self._client.request(
  File "/Users/airhao3/miniconda3/envs/bot/lib/python3.10/site-packages/httpx/_client.py", line 1574, in request
    return await self.send(request, auth=auth, follow_redirects=follow_redirects)
  File "/Users/airhao3/miniconda3/envs/bot/lib/python3.10/site-packages/httpx/_client.py", line 1661, in send
    response = await self._send_handling_auth(
  File "/Users/airhao3/miniconda3/envs/bot/lib/python3.10/site-packages/httpx/_client.py", line 1689, in _send_handling_auth
    response = await self._send_handling_redirects(
  File "/Users/airhao3/miniconda3/envs/bot/lib/python3.10/site-packages/httpx/_client.py", line 1726, in _send_handling_redirects
    response = await self._send_single_request(request)
  File "/Users/airhao3/miniconda3/envs/bot/lib/python3.10/site-packages/httpx/_client.py", line 1763, in _send_single_request
    response = await transport.handle_async_request(request)
  File "/Users/airhao3/miniconda3/envs/bot/lib/python3.10/site-packages/httpx/_transports/default.py", line 372, in handle_async_request
    with map_httpcore_exceptions():
  File "/Users/airhao3/miniconda3/envs/bot/lib/python3.10/contextlib.py", line 153, in __exit__
    self.gen.throw(typ, value, traceback)
  File "/Users/airhao3/miniconda3/envs/bot/lib/python3.10/site-packages/httpx/_transports/default.py", line 86, in map_httpcore_exceptions
    raise mapped_exc(message) from exc
httpx.ConnectTimeout

The above exception was the direct cause of the following exception:

Traceback (most recent call last):
  File "/Users/airhao3/miniconda3/envs/bot/lib/python3.10/site-packages/telegram/ext/_application.py", line 1335, in process_update
    await coroutine
  File "/Users/airhao3/miniconda3/envs/bot/lib/python3.10/site-packages/telegram/ext/_handlers/basehandler.py", line 157, in handle_update
    return await self.callback(update, context)
  File "/Users/airhao3/nextcloud/document/telegram-bot-python/telegram-bot-download-proxy.py", line 130, in download_video
    await update.message.reply_text("This is not a valid URL. Please send a video URL.")
  File "/Users/airhao3/miniconda3/envs/bot/lib/python3.10/site-packages/telegram/_message.py", line 1763, in reply_text
    return await self.get_bot().send_message(
  File "/Users/airhao3/miniconda3/envs/bot/lib/python3.10/site-packages/telegram/ext/_extbot.py", line 2907, in send_message
    return await super().send_message(
  File "/Users/airhao3/miniconda3/envs/bot/lib/python3.10/site-packages/telegram/_bot.py", line 1028, in send_message
    return await self._send_message(
  File "/Users/airhao3/miniconda3/envs/bot/lib/python3.10/site-packages/telegram/ext/_extbot.py", line 610, in _send_message
    result = await super()._send_message(
  File "/Users/airhao3/miniconda3/envs/bot/lib/python3.10/site-packages/telegram/_bot.py", line 744, in _send_message
    result = await self._post(
  File "/Users/airhao3/miniconda3/envs/bot/lib/python3.10/site-packages/telegram/_bot.py", line 622, in _post
    return await self._do_post(
  File "/Users/airhao3/miniconda3/envs/bot/lib/python3.10/site-packages/telegram/ext/_extbot.py", line 355, in _do_post
    return await super()._do_post(
  File "/Users/airhao3/miniconda3/envs/bot/lib/python3.10/site-packages/telegram/_bot.py", line 651, in _do_post
    result = await request.post(
  File "/Users/airhao3/miniconda3/envs/bot/lib/python3.10/site-packages/telegram/request/_baserequest.py", line 200, in post
    result = await self._request_wrapper(
  File "/Users/airhao3/miniconda3/envs/bot/lib/python3.10/site-packages/telegram/request/_baserequest.py", line 342, in _request_wrapper
    raise exc
  File "/Users/airhao3/miniconda3/envs/bot/lib/python3.10/site-packages/telegram/request/_baserequest.py", line 332, in _request_wrapper
    code, payload = await self.do_request(
  File "/Users/airhao3/miniconda3/envs/bot/lib/python3.10/site-packages/telegram/request/_httpxrequest.py", line 293, in do_request
    raise TimedOut from err
telegram.error.TimedOut: Timed out
2024-07-22 15:19:48,042 - httpx - INFO - HTTP Request: POST https://api.telegram.org/bot7064977852:AAGEEutTl0D6gVt-Jgz4aXJ4mxK8mLPdL_E/getUpdates "HTTP/1.1 200 OK"
2024-07-22 15:19:48,044 - __main__ - INFO - Received message from user 2042811943 (None): https://youtube.com/shorts/cnGJ86yf0cM?si=RlZ0yX6baDDHjUJF
2024-07-22 15:19:53,049 - telegram.ext.Application - ERROR - No error handlers are registered, logging exception.
Traceback (most recent call last):
  File "/Users/airhao3/miniconda3/envs/bot/lib/python3.10/site-packages/httpx/_transports/default.py", line 69, in map_httpcore_exceptions
    yield
  File "/Users/airhao3/miniconda3/envs/bot/lib/python3.10/site-packages/httpx/_transports/default.py", line 373, in handle_async_request
    resp = await self._pool.handle_async_request(req)
  File "/Users/airhao3/miniconda3/envs/bot/lib/python3.10/site-packages/httpcore/_async/connection_pool.py", line 216, in handle_async_request
    raise exc from None
  File "/Users/airhao3/miniconda3/envs/bot/lib/python3.10/site-packages/httpcore/_async/connection_pool.py", line 196, in handle_async_request
    response = await connection.handle_async_request(
  File "/Users/airhao3/miniconda3/envs/bot/lib/python3.10/site-packages/httpcore/_async/socks_proxy.py", line 296, in handle_async_request
    raise exc
  File "/Users/airhao3/miniconda3/envs/bot/lib/python3.10/site-packages/httpcore/_async/socks_proxy.py", line 267, in handle_async_request
    stream = await stream.start_tls(**kwargs)
  File "/Users/airhao3/miniconda3/envs/bot/lib/python3.10/site-packages/httpcore/_backends/anyio.py", line 68, in start_tls
    with map_exceptions(exc_map):
  File "/Users/airhao3/miniconda3/envs/bot/lib/python3.10/contextlib.py", line 153, in __exit__
    self.gen.throw(typ, value, traceback)
  File "/Users/airhao3/miniconda3/envs/bot/lib/python3.10/site-packages/httpcore/_exceptions.py", line 14, in map_exceptions
    raise to_exc(exc) from exc
httpcore.ConnectTimeout

The above exception was the direct cause of the following exception:

Traceback (most recent call last):
  File "/Users/airhao3/miniconda3/envs/bot/lib/python3.10/site-packages/telegram/request/_httpxrequest.py", line 276, in do_request
    res = await self._client.request(
  File "/Users/airhao3/miniconda3/envs/bot/lib/python3.10/site-packages/httpx/_client.py", line 1574, in request
    return await self.send(request, auth=auth, follow_redirects=follow_redirects)
  File "/Users/airhao3/miniconda3/envs/bot/lib/python3.10/site-packages/httpx/_client.py", line 1661, in send
    response = await self._send_handling_auth(
  File "/Users/airhao3/miniconda3/envs/bot/lib/python3.10/site-packages/httpx/_client.py", line 1689, in _send_handling_auth
    response = await self._send_handling_redirects(
  File "/Users/airhao3/miniconda3/envs/bot/lib/python3.10/site-packages/httpx/_client.py", line 1726, in _send_handling_redirects
    response = await self._send_single_request(request)
  File "/Users/airhao3/miniconda3/envs/bot/lib/python3.10/site-packages/httpx/_client.py", line 1763, in _send_single_request
    response = await transport.handle_async_request(request)
  File "/Users/airhao3/miniconda3/envs/bot/lib/python3.10/site-packages/httpx/_transports/default.py", line 372, in handle_async_request
    with map_httpcore_exceptions():
  File "/Users/airhao3/miniconda3/envs/bot/lib/python3.10/contextlib.py", line 153, in __exit__
    self.gen.throw(typ, value, traceback)
  File "/Users/airhao3/miniconda3/envs/bot/lib/python3.10/site-packages/httpx/_transports/default.py", line 86, in map_httpcore_exceptions
    raise mapped_exc(message) from exc
httpx.ConnectTimeout

The above exception was the direct cause of the following exception:

Traceback (most recent call last):
  File "/Users/airhao3/miniconda3/envs/bot/lib/python3.10/site-packages/telegram/ext/_application.py", line 1335, in process_update
    await coroutine
  File "/Users/airhao3/miniconda3/envs/bot/lib/python3.10/site-packages/telegram/ext/_handlers/basehandler.py", line 157, in handle_update
    return await self.callback(update, context)
  File "/Users/airhao3/nextcloud/document/telegram-bot-python/telegram-bot-download-proxy.py", line 109, in download_video
    status_message = await update.message.reply_text("Starting download. Please wait...")
  File "/Users/airhao3/miniconda3/envs/bot/lib/python3.10/site-packages/telegram/_message.py", line 1763, in reply_text
    return await self.get_bot().send_message(
  File "/Users/airhao3/miniconda3/envs/bot/lib/python3.10/site-packages/telegram/ext/_extbot.py", line 2907, in send_message
    return await super().send_message(
  File "/Users/airhao3/miniconda3/envs/bot/lib/python3.10/site-packages/telegram/_bot.py", line 1028, in send_message
    return await self._send_message(
  File "/Users/airhao3/miniconda3/envs/bot/lib/python3.10/site-packages/telegram/ext/_extbot.py", line 610, in _send_message
    result = await super()._send_message(
  File "/Users/airhao3/miniconda3/envs/bot/lib/python3.10/site-packages/telegram/_bot.py", line 744, in _send_message
    result = await self._post(
  File "/Users/airhao3/miniconda3/envs/bot/lib/python3.10/site-packages/telegram/_bot.py", line 622, in _post
    return await self._do_post(
  File "/Users/airhao3/miniconda3/envs/bot/lib/python3.10/site-packages/telegram/ext/_extbot.py", line 355, in _do_post
    return await super()._do_post(
  File "/Users/airhao3/miniconda3/envs/bot/lib/python3.10/site-packages/telegram/_bot.py", line 651, in _do_post
    result = await request.post(
  File "/Users/airhao3/miniconda3/envs/bot/lib/python3.10/site-packages/telegram/request/_baserequest.py", line 200, in post
    result = await self._request_wrapper(
  File "/Users/airhao3/miniconda3/envs/bot/lib/python3.10/site-packages/telegram/request/_baserequest.py", line 342, in _request_wrapper
    raise exc
  File "/Users/airhao3/miniconda3/envs/bot/lib/python3.10/site-packages/telegram/request/_baserequest.py", line 332, in _request_wrapper
    code, payload = await self.do_request(
  File "/Users/airhao3/miniconda3/envs/bot/lib/python3.10/site-packages/telegram/request/_httpxrequest.py", line 293, in do_request
    raise TimedOut from err
telegram.error.TimedOut: Timed out
2024-07-22 15:19:58,310 - httpx - INFO - HTTP Request: POST https://api.telegram.org/bot7064977852:AAGEEutTl0D6gVt-Jgz4aXJ4mxK8mLPdL_E/getUpdates "HTTP/1.1 200 OK"
2024-07-22 15:20:08,564 - httpx - INFO - HTTP Request: POST https://api.telegram.org/bot7064977852:AAGEEutTl0D6gVt-Jgz4aXJ4mxK8mLPdL_E/getUpdates "HTTP/1.1 200 OK"
2024-07-22 15:20:18,895 - httpx - INFO - HTTP Request: POST https://api.telegram.org/bot7064977852:AAGEEutTl0D6gVt-Jgz4aXJ4mxK8mLPdL_E/getUpdates "HTTP/1.1 200 OK"
2024-07-22 15:20:29,150 - httpx - INFO - HTTP Request: POST https://api.telegram.org/bot7064977852:AAGEEutTl0D6gVt-Jgz4aXJ4mxK8mLPdL_E/getUpdates "HTTP/1.1 200 OK"
2024-07-22 15:20:39,404 - httpx - INFO - HTTP Request: POST https://api.telegram.org/bot7064977852:AAGEEutTl0D6gVt-Jgz4aXJ4mxK8mLPdL_E/getUpdates "HTTP/1.1 200 OK"
2024-07-22 15:20:49,680 - httpx - INFO - HTTP Request: POST https://api.telegram.org/bot7064977852:AAGEEutTl0D6gVt-Jgz4aXJ4mxK8mLPdL_E/getUpdates "HTTP/1.1 200 OK"
2024-07-22 15:20:59,962 - httpx - INFO - HTTP Request: POST https://api.telegram.org/bot7064977852:AAGEEutTl0D6gVt-Jgz4aXJ4mxK8mLPdL_E/getUpdates "HTTP/1.1 200 OK"
2024-07-22 15:21:10,212 - httpx - INFO - HTTP Request: POST https://api.telegram.org/bot7064977852:AAGEEutTl0D6gVt-Jgz4aXJ4mxK8mLPdL_E/getUpdates "HTTP/1.1 200 OK"
2024-07-22 15:21:20,474 - httpx - INFO - HTTP Request: POST https://api.telegram.org/bot7064977852:AAGEEutTl0D6gVt-Jgz4aXJ4mxK8mLPdL_E/getUpdates "HTTP/1.1 200 OK"
2024-07-22 15:21:30,728 - httpx - INFO - HTTP Request: POST https://api.telegram.org/bot7064977852:AAGEEutTl0D6gVt-Jgz4aXJ4mxK8mLPdL_E/getUpdates "HTTP/1.1 200 OK"
2024-07-22 15:21:41,448 - httpx - INFO - HTTP Request: POST https://api.telegram.org/bot7064977852:AAGEEutTl0D6gVt-Jgz4aXJ4mxK8mLPdL_E/getUpdates "HTTP/1.1 200 OK"
2024-07-22 15:21:51,716 - httpx - INFO - HTTP Request: POST https://api.telegram.org/bot7064977852:AAGEEutTl0D6gVt-Jgz4aXJ4mxK8mLPdL_E/getUpdates "HTTP/1.1 200 OK"
2024-07-22 15:22:01,966 - httpx - INFO - HTTP Request: POST https://api.telegram.org/bot7064977852:AAGEEutTl0D6gVt-Jgz4aXJ4mxK8mLPdL_E/getUpdates "HTTP/1.1 200 OK"
2024-07-22 15:22:12,232 - httpx - INFO - HTTP Request: POST https://api.telegram.org/bot7064977852:AAGEEutTl0D6gVt-Jgz4aXJ4mxK8mLPdL_E/getUpdates "HTTP/1.1 200 OK"
2024-07-22 15:22:22,499 - httpx - INFO - HTTP Request: POST https://api.telegram.org/bot7064977852:AAGEEutTl0D6gVt-Jgz4aXJ4mxK8mLPdL_E/getUpdates "HTTP/1.1 200 OK"
2024-07-22 15:22:32,753 - httpx - INFO - HTTP Request: POST https://api.telegram.org/bot7064977852:AAGEEutTl0D6gVt-Jgz4aXJ4mxK8mLPdL_E/getUpdates "HTTP/1.1 200 OK"
2024-07-22 15:22:43,011 - httpx - INFO - HTTP Request: POST https://api.telegram.org/bot7064977852:AAGEEutTl0D6gVt-Jgz4aXJ4mxK8mLPdL_E/getUpdates "HTTP/1.1 200 OK"
2024-07-22 15:22:53,265 - httpx - INFO - HTTP Request: POST https://api.telegram.org/bot7064977852:AAGEEutTl0D6gVt-Jgz4aXJ4mxK8mLPdL_E/getUpdates "HTTP/1.1 200 OK"
2024-07-22 15:23:03,515 - httpx - INFO - HTTP Request: POST https://api.telegram.org/bot7064977852:AAGEEutTl0D6gVt-Jgz4aXJ4mxK8mLPdL_E/getUpdates "HTTP/1.1 200 OK"
2024-07-22 15:23:13,759 - httpx - INFO - HTTP Request: POST https://api.telegram.org/bot7064977852:AAGEEutTl0D6gVt-Jgz4aXJ4mxK8mLPdL_E/getUpdates "HTTP/1.1 200 OK"
2024-07-22 15:23:24,107 - httpx - INFO - HTTP Request: POST https://api.telegram.org/bot7064977852:AAGEEutTl0D6gVt-Jgz4aXJ4mxK8mLPdL_E/getUpdates "HTTP/1.1 200 OK"
2024-07-22 15:23:34,388 - httpx - INFO - HTTP Request: POST https://api.telegram.org/bot7064977852:AAGEEutTl0D6gVt-Jgz4aXJ4mxK8mLPdL_E/getUpdates "HTTP/1.1 200 OK"
2024-07-22 15:23:44,647 - httpx - INFO - HTTP Request: POST https://api.telegram.org/bot7064977852:AAGEEutTl0D6gVt-Jgz4aXJ4mxK8mLPdL_E/getUpdates "HTTP/1.1 200 OK"
2024-07-22 15:23:55,365 - httpx - INFO - HTTP Request: POST https://api.telegram.org/bot7064977852:AAGEEutTl0D6gVt-Jgz4aXJ4mxK8mLPdL_E/getUpdates "HTTP/1.1 200 OK"
2024-07-22 15:24:05,647 - httpx - INFO - HTTP Request: POST https://api.telegram.org/bot7064977852:AAGEEutTl0D6gVt-Jgz4aXJ4mxK8mLPdL_E/getUpdates "HTTP/1.1 200 OK"
2024-07-22 15:24:16,033 - httpx - INFO - HTTP Request: POST https://api.telegram.org/bot7064977852:AAGEEutTl0D6gVt-Jgz4aXJ4mxK8mLPdL_E/getUpdates "HTTP/1.1 200 OK"
2024-07-22 15:24:26,285 - httpx - INFO - HTTP Request: POST https://api.telegram.org/bot7064977852:AAGEEutTl0D6gVt-Jgz4aXJ4mxK8mLPdL_E/getUpdates "HTTP/1.1 200 OK"
2024-07-22 15:24:36,605 - httpx - INFO - HTTP Request: POST https://api.telegram.org/bot7064977852:AAGEEutTl0D6gVt-Jgz4aXJ4mxK8mLPdL_E/getUpdates "HTTP/1.1 200 OK"
2024-07-22 15:24:46,863 - httpx - INFO - HTTP Request: POST https://api.telegram.org/bot7064977852:AAGEEutTl0D6gVt-Jgz4aXJ4mxK8mLPdL_E/getUpdates "HTTP/1.1 200 OK"
2024-07-22 15:24:57,633 - httpx - INFO - HTTP Request: POST https://api.telegram.org/bot7064977852:AAGEEutTl0D6gVt-Jgz4aXJ4mxK8mLPdL_E/getUpdates "HTTP/1.1 200 OK"
2024-07-22 15:25:07,932 - httpx - INFO - HTTP Request: POST https://api.telegram.org/bot7064977852:AAGEEutTl0D6gVt-Jgz4aXJ4mxK8mLPdL_E/getUpdates "HTTP/1.1 200 OK"
2024-07-22 15:25:18,227 - httpx - INFO - HTTP Request: POST https://api.telegram.org/bot7064977852:AAGEEutTl0D6gVt-Jgz4aXJ4mxK8mLPdL_E/getUpdates "HTTP/1.1 200 OK"
2024-07-22 15:25:28,496 - httpx - INFO - HTTP Request: POST https://api.telegram.org/bot7064977852:AAGEEutTl0D6gVt-Jgz4aXJ4mxK8mLPdL_E/getUpdates "HTTP/1.1 200 OK"
2024-07-22 15:25:38,755 - httpx - INFO - HTTP Request: POST https://api.telegram.org/bot7064977852:AAGEEutTl0D6gVt-Jgz4aXJ4mxK8mLPdL_E/getUpdates "HTTP/1.1 200 OK"
2024-07-22 15:25:49,009 - httpx - INFO - HTTP Request: POST https://api.telegram.org/bot7064977852:AAGEEutTl0D6gVt-Jgz4aXJ4mxK8mLPdL_E/getUpdates "HTTP/1.1 200 OK"
2024-07-22 15:25:59,263 - httpx - INFO - HTTP Request: POST https://api.telegram.org/bot7064977852:AAGEEutTl0D6gVt-Jgz4aXJ4mxK8mLPdL_E/getUpdates "HTTP/1.1 200 OK"
2024-07-22 15:26:09,550 - httpx - INFO - HTTP Request: POST https://api.telegram.org/bot7064977852:AAGEEutTl0D6gVt-Jgz4aXJ4mxK8mLPdL_E/getUpdates "HTTP/1.1 200 OK"
2024-07-22 15:26:19,801 - httpx - INFO - HTTP Request: POST https://api.telegram.org/bot7064977852:AAGEEutTl0D6gVt-Jgz4aXJ4mxK8mLPdL_E/getUpdates "HTTP/1.1 200 OK"
2024-07-22 15:26:30,059 - httpx - INFO - HTTP Request: POST https://api.telegram.org/bot7064977852:AAGEEutTl0D6gVt-Jgz4aXJ4mxK8mLPdL_E/getUpdates "HTTP/1.1 200 OK"
2024-07-22 15:26:40,321 - httpx - INFO - HTTP Request: POST https://api.telegram.org/bot7064977852:AAGEEutTl0D6gVt-Jgz4aXJ4mxK8mLPdL_E/getUpdates "HTTP/1.1 200 OK"
2024-07-22 15:26:50,641 - httpx - INFO - HTTP Request: POST https://api.telegram.org/bot7064977852:AAGEEutTl0D6gVt-Jgz4aXJ4mxK8mLPdL_E/getUpdates "HTTP/1.1 200 OK"
2024-07-22 15:27:00,895 - httpx - INFO - HTTP Request: POST https://api.telegram.org/bot7064977852:AAGEEutTl0D6gVt-Jgz4aXJ4mxK8mLPdL_E/getUpdates "HTTP/1.1 200 OK"
2024-07-22 15:27:11,152 - httpx - INFO - HTTP Request: POST https://api.telegram.org/bot7064977852:AAGEEutTl0D6gVt-Jgz4aXJ4mxK8mLPdL_E/getUpdates "HTTP/1.1 200 OK"
2024-07-22 15:27:21,907 - httpx - INFO - HTTP Request: POST https://api.telegram.org/bot7064977852:AAGEEutTl0D6gVt-Jgz4aXJ4mxK8mLPdL_E/getUpdates "HTTP/1.1 200 OK"
2024-07-22 15:27:32,168 - httpx - INFO - HTTP Request: POST https://api.telegram.org/bot7064977852:AAGEEutTl0D6gVt-Jgz4aXJ4mxK8mLPdL_E/getUpdates "HTTP/1.1 200 OK"
2024-07-22 15:27:42,475 - httpx - INFO - HTTP Request: POST https://api.telegram.org/bot7064977852:AAGEEutTl0D6gVt-Jgz4aXJ4mxK8mLPdL_E/getUpdates "HTTP/1.1 200 OK"
2024-07-22 15:27:52,743 - httpx - INFO - HTTP Request: POST https://api.telegram.org/bot7064977852:AAGEEutTl0D6gVt-Jgz4aXJ4mxK8mLPdL_E/getUpdates "HTTP/1.1 200 OK"
2024-07-22 15:28:03,008 - httpx - INFO - HTTP Request: POST https://api.telegram.org/bot7064977852:AAGEEutTl0D6gVt-Jgz4aXJ4mxK8mLPdL_E/getUpdates "HTTP/1.1 200 OK"
2024-07-22 15:28:13,303 - httpx - INFO - HTTP Request: POST https://api.telegram.org/bot7064977852:AAGEEutTl0D6gVt-Jgz4aXJ4mxK8mLPdL_E/getUpdates "HTTP/1.1 200 OK"
2024-07-22 15:28:23,556 - httpx - INFO - HTTP Request: POST https://api.telegram.org/bot7064977852:AAGEEutTl0D6gVt-Jgz4aXJ4mxK8mLPdL_E/getUpdates "HTTP/1.1 200 OK"
2024-07-22 15:28:33,846 - httpx - INFO - HTTP Request: POST https://api.telegram.org/bot7064977852:AAGEEutTl0D6gVt-Jgz4aXJ4mxK8mLPdL_E/getUpdates "HTTP/1.1 200 OK"
2024-07-22 15:28:44,109 - httpx - INFO - HTTP Request: POST https://api.telegram.org/bot7064977852:AAGEEutTl0D6gVt-Jgz4aXJ4mxK8mLPdL_E/getUpdates "HTTP/1.1 200 OK"
2024-07-22 15:28:54,413 - httpx - INFO - HTTP Request: POST https://api.telegram.org/bot7064977852:AAGEEutTl0D6gVt-Jgz4aXJ4mxK8mLPdL_E/getUpdates "HTTP/1.1 200 OK"
2024-07-22 15:29:04,685 - httpx - INFO - HTTP Request: POST https://api.telegram.org/bot7064977852:AAGEEutTl0D6gVt-Jgz4aXJ4mxK8mLPdL_E/getUpdates "HTTP/1.1 200 OK"
2024-07-22 15:29:14,941 - httpx - INFO - HTTP Request: POST https://api.telegram.org/bot7064977852:AAGEEutTl0D6gVt-Jgz4aXJ4mxK8mLPdL_E/getUpdates "HTTP/1.1 200 OK"
2024-07-22 15:29:25,201 - httpx - INFO - HTTP Request: POST https://api.telegram.org/bot7064977852:AAGEEutTl0D6gVt-Jgz4aXJ4mxK8mLPdL_E/getUpdates "HTTP/1.1 200 OK"
2024-07-22 15:29:35,452 - httpx - INFO - HTTP Request: POST https://api.telegram.org/bot7064977852:AAGEEutTl0D6gVt-Jgz4aXJ4mxK8mLPdL_E/getUpdates "HTTP/1.1 200 OK"
2024-07-22 15:29:45,710 - httpx - INFO - HTTP Request: POST https://api.telegram.org/bot7064977852:AAGEEutTl0D6gVt-Jgz4aXJ4mxK8mLPdL_E/getUpdates "HTTP/1.1 200 OK"
2024-07-22 15:29:55,971 - httpx - INFO - HTTP Request: POST https://api.telegram.org/bot7064977852:AAGEEutTl0D6gVt-Jgz4aXJ4mxK8mLPdL_E/getUpdates "HTTP/1.1 200 OK"
2024-07-22 15:30:06,352 - httpx - INFO - HTTP Request: POST https://api.telegram.org/bot7064977852:AAGEEutTl0D6gVt-Jgz4aXJ4mxK8mLPdL_E/getUpdates "HTTP/1.1 200 OK"
2024-07-22 15:30:16,625 - httpx - INFO - HTTP Request: POST https://api.telegram.org/bot7064977852:AAGEEutTl0D6gVt-Jgz4aXJ4mxK8mLPdL_E/getUpdates "HTTP/1.1 200 OK"
2024-07-22 15:30:26,903 - httpx - INFO - HTTP Request: POST https://api.telegram.org/bot7064977852:AAGEEutTl0D6gVt-Jgz4aXJ4mxK8mLPdL_E/getUpdates "HTTP/1.1 200 OK"
2024-07-22 15:30:37,203 - httpx - INFO - HTTP Request: POST https://api.telegram.org/bot7064977852:AAGEEutTl0D6gVt-Jgz4aXJ4mxK8mLPdL_E/getUpdates "HTTP/1.1 200 OK"
2024-07-22 15:30:47,603 - httpx - INFO - HTTP Request: POST https://api.telegram.org/bot7064977852:AAGEEutTl0D6gVt-Jgz4aXJ4mxK8mLPdL_E/getUpdates "HTTP/1.1 200 OK"
2024-07-22 15:30:57,854 - httpx - INFO - HTTP Request: POST https://api.telegram.org/bot7064977852:AAGEEutTl0D6gVt-Jgz4aXJ4mxK8mLPdL_E/getUpdates "HTTP/1.1 200 OK"
2024-07-22 15:31:08,105 - httpx - INFO - HTTP Request: POST https://api.telegram.org/bot7064977852:AAGEEutTl0D6gVt-Jgz4aXJ4mxK8mLPdL_E/getUpdates "HTTP/1.1 200 OK"
2024-07-22 15:31:18,361 - httpx - INFO - HTTP Request: POST https://api.telegram.org/bot7064977852:AAGEEutTl0D6gVt-Jgz4aXJ4mxK8mLPdL_E/getUpdates "HTTP/1.1 200 OK"
2024-07-22 15:31:28,616 - httpx - INFO - HTTP Request: POST https://api.telegram.org/bot7064977852:AAGEEutTl0D6gVt-Jgz4aXJ4mxK8mLPdL_E/getUpdates "HTTP/1.1 200 OK"
2024-07-22 15:31:38,905 - httpx - INFO - HTTP Request: POST https://api.telegram.org/bot7064977852:AAGEEutTl0D6gVt-Jgz4aXJ4mxK8mLPdL_E/getUpdates "HTTP/1.1 200 OK"
2024-07-22 15:31:49,164 - httpx - INFO - HTTP Request: POST https://api.telegram.org/bot7064977852:AAGEEutTl0D6gVt-Jgz4aXJ4mxK8mLPdL_E/getUpdates "HTTP/1.1 200 OK"
2024-07-22 15:31:59,421 - httpx - INFO - HTTP Request: POST https://api.telegram.org/bot7064977852:AAGEEutTl0D6gVt-Jgz4aXJ4mxK8mLPdL_E/getUpdates "HTTP/1.1 200 OK"
2024-07-22 15:32:09,707 - httpx - INFO - HTTP Request: POST https://api.telegram.org/bot7064977852:AAGEEutTl0D6gVt-Jgz4aXJ4mxK8mLPdL_E/getUpdates "HTTP/1.1 200 OK"
2024-07-22 15:32:19,971 - httpx - INFO - HTTP Request: POST https://api.telegram.org/bot7064977852:AAGEEutTl0D6gVt-Jgz4aXJ4mxK8mLPdL_E/getUpdates "HTTP/1.1 200 OK"
2024-07-22 15:32:30,232 - httpx - INFO - HTTP Request: POST https://api.telegram.org/bot7064977852:AAGEEutTl0D6gVt-Jgz4aXJ4mxK8mLPdL_E/getUpdates "HTTP/1.1 200 OK"
2024-07-22 15:32:40,484 - httpx - INFO - HTTP Request: POST https://api.telegram.org/bot7064977852:AAGEEutTl0D6gVt-Jgz4aXJ4mxK8mLPdL_E/getUpdates "HTTP/1.1 200 OK"
2024-07-22 15:32:51,963 - httpx - INFO - HTTP Request: POST https://api.telegram.org/bot7064977852:AAGEEutTl0D6gVt-Jgz4aXJ4mxK8mLPdL_E/getUpdates "HTTP/1.1 200 OK"
2024-07-22 15:33:02,269 - httpx - INFO - HTTP Request: POST https://api.telegram.org/bot7064977852:AAGEEutTl0D6gVt-Jgz4aXJ4mxK8mLPdL_E/getUpdates "HTTP/1.1 200 OK"
2024-07-22 15:33:12,526 - httpx - INFO - HTTP Request: POST https://api.telegram.org/bot7064977852:AAGEEutTl0D6gVt-Jgz4aXJ4mxK8mLPdL_E/getUpdates "HTTP/1.1 200 OK"
2024-07-22 15:33:22,790 - httpx - INFO - HTTP Request: POST https://api.telegram.org/bot7064977852:AAGEEutTl0D6gVt-Jgz4aXJ4mxK8mLPdL_E/getUpdates "HTTP/1.1 200 OK"
2024-07-22 15:33:33,050 - httpx - INFO - HTTP Request: POST https://api.telegram.org/bot7064977852:AAGEEutTl0D6gVt-Jgz4aXJ4mxK8mLPdL_E/getUpdates "HTTP/1.1 200 OK"
2024-07-22 15:33:43,305 - httpx - INFO - HTTP Request: POST https://api.telegram.org/bot7064977852:AAGEEutTl0D6gVt-Jgz4aXJ4mxK8mLPdL_E/getUpdates "HTTP/1.1 200 OK"
2024-07-22 15:33:53,570 - httpx - INFO - HTTP Request: POST https://api.telegram.org/bot7064977852:AAGEEutTl0D6gVt-Jgz4aXJ4mxK8mLPdL_E/getUpdates "HTTP/1.1 200 OK"
2024-07-22 15:34:03,826 - httpx - INFO - HTTP Request: POST https://api.telegram.org/bot7064977852:AAGEEutTl0D6gVt-Jgz4aXJ4mxK8mLPdL_E/getUpdates "HTTP/1.1 200 OK"
2024-07-22 15:34:14,079 - httpx - INFO - HTTP Request: POST https://api.telegram.org/bot7064977852:AAGEEutTl0D6gVt-Jgz4aXJ4mxK8mLPdL_E/getUpdates "HTTP/1.1 200 OK"
2024-07-22 15:34:24,390 - httpx - INFO - HTTP Request: POST https://api.telegram.org/bot7064977852:AAGEEutTl0D6gVt-Jgz4aXJ4mxK8mLPdL_E/getUpdates "HTTP/1.1 200 OK"
2024-07-22 15:34:34,644 - httpx - INFO - HTTP Request: POST https://api.telegram.org/bot7064977852:AAGEEutTl0D6gVt-Jgz4aXJ4mxK8mLPdL_E/getUpdates "HTTP/1.1 200 OK"
2024-07-22 15:34:45,396 - httpx - INFO - HTTP Request: POST https://api.telegram.org/bot7064977852:AAGEEutTl0D6gVt-Jgz4aXJ4mxK8mLPdL_E/getUpdates "HTTP/1.1 200 OK"
2024-07-22 15:34:55,683 - httpx - INFO - HTTP Request: POST https://api.telegram.org/bot7064977852:AAGEEutTl0D6gVt-Jgz4aXJ4mxK8mLPdL_E/getUpdates "HTTP/1.1 200 OK"
2024-07-22 15:35:05,938 - httpx - INFO - HTTP Request: POST https://api.telegram.org/bot7064977852:AAGEEutTl0D6gVt-Jgz4aXJ4mxK8mLPdL_E/getUpdates "HTTP/1.1 200 OK"
2024-07-22 15:35:16,187 - httpx - INFO - HTTP Request: POST https://api.telegram.org/bot7064977852:AAGEEutTl0D6gVt-Jgz4aXJ4mxK8mLPdL_E/getUpdates "HTTP/1.1 200 OK"
2024-07-22 15:35:26,492 - httpx - INFO - HTTP Request: POST https://api.telegram.org/bot7064977852:AAGEEutTl0D6gVt-Jgz4aXJ4mxK8mLPdL_E/getUpdates "HTTP/1.1 200 OK"
2024-07-22 15:35:36,754 - httpx - INFO - HTTP Request: POST https://api.telegram.org/bot7064977852:AAGEEutTl0D6gVt-Jgz4aXJ4mxK8mLPdL_E/getUpdates "HTTP/1.1 200 OK"
2024-07-22 15:35:47,008 - httpx - INFO - HTTP Request: POST https://api.telegram.org/bot7064977852:AAGEEutTl0D6gVt-Jgz4aXJ4mxK8mLPdL_E/getUpdates "HTTP/1.1 200 OK"
2024-07-22 15:35:57,270 - httpx - INFO - HTTP Request: POST https://api.telegram.org/bot7064977852:AAGEEutTl0D6gVt-Jgz4aXJ4mxK8mLPdL_E/getUpdates "HTTP/1.1 200 OK"
2024-07-22 15:36:07,522 - httpx - INFO - HTTP Request: POST https://api.telegram.org/bot7064977852:AAGEEutTl0D6gVt-Jgz4aXJ4mxK8mLPdL_E/getUpdates "HTTP/1.1 200 OK"
2024-07-22 15:36:17,773 - httpx - INFO - HTTP Request: POST https://api.telegram.org/bot7064977852:AAGEEutTl0D6gVt-Jgz4aXJ4mxK8mLPdL_E/getUpdates "HTTP/1.1 200 OK"
2024-07-22 15:36:28,042 - httpx - INFO - HTTP Request: POST https://api.telegram.org/bot7064977852:AAGEEutTl0D6gVt-Jgz4aXJ4mxK8mLPdL_E/getUpdates "HTTP/1.1 200 OK"
2024-07-22 15:36:38,771 - httpx - INFO - HTTP Request: POST https://api.telegram.org/bot7064977852:AAGEEutTl0D6gVt-Jgz4aXJ4mxK8mLPdL_E/getUpdates "HTTP/1.1 200 OK"
2024-07-22 15:36:49,027 - httpx - INFO - HTTP Request: POST https://api.telegram.org/bot7064977852:AAGEEutTl0D6gVt-Jgz4aXJ4mxK8mLPdL_E/getUpdates "HTTP/1.1 200 OK"
2024-07-22 15:36:59,273 - httpx - INFO - HTTP Request: POST https://api.telegram.org/bot7064977852:AAGEEutTl0D6gVt-Jgz4aXJ4mxK8mLPdL_E/getUpdates "HTTP/1.1 200 OK"
2024-07-22 15:37:09,596 - httpx - INFO - HTTP Request: POST https://api.telegram.org/bot7064977852:AAGEEutTl0D6gVt-Jgz4aXJ4mxK8mLPdL_E/getUpdates "HTTP/1.1 200 OK"
2024-07-22 15:37:19,864 - httpx - INFO - HTTP Request: POST https://api.telegram.org/bot7064977852:AAGEEutTl0D6gVt-Jgz4aXJ4mxK8mLPdL_E/getUpdates "HTTP/1.1 200 OK"
2024-07-22 15:37:30,162 - httpx - INFO - HTTP Request: POST https://api.telegram.org/bot7064977852:AAGEEutTl0D6gVt-Jgz4aXJ4mxK8mLPdL_E/getUpdates "HTTP/1.1 200 OK"
2024-07-22 15:37:40,432 - httpx - INFO - HTTP Request: POST https://api.telegram.org/bot7064977852:AAGEEutTl0D6gVt-Jgz4aXJ4mxK8mLPdL_E/getUpdates "HTTP/1.1 200 OK"
2024-07-22 15:37:50,694 - httpx - INFO - HTTP Request: POST https://api.telegram.org/bot7064977852:AAGEEutTl0D6gVt-Jgz4aXJ4mxK8mLPdL_E/getUpdates "HTTP/1.1 200 OK"
2024-07-22 15:38:00,853 - httpx - INFO - HTTP Request: POST https://api.telegram.org/bot7064977852:AAGEEutTl0D6gVt-Jgz4aXJ4mxK8mLPdL_E/getUpdates "HTTP/1.1 200 OK"
2024-07-22 15:38:11,127 - httpx - INFO - HTTP Request: POST https://api.telegram.org/bot7064977852:AAGEEutTl0D6gVt-Jgz4aXJ4mxK8mLPdL_E/getUpdates "HTTP/1.1 200 OK"
2024-07-22 15:38:21,396 - httpx - INFO - HTTP Request: POST https://api.telegram.org/bot7064977852:AAGEEutTl0D6gVt-Jgz4aXJ4mxK8mLPdL_E/getUpdates "HTTP/1.1 200 OK"
2024-07-22 15:38:25,939 - httpx - INFO - HTTP Request: POST https://api.telegram.org/bot7064977852:AAGEEutTl0D6gVt-Jgz4aXJ4mxK8mLPdL_E/getUpdates "HTTP/1.1 200 OK"
2024-07-22 15:38:25,940 - __main__ - INFO - Received message from user 2042811943 (None): jo
2024-07-22 15:38:25,941 - __main__ - WARNING - User 2042811943 (None) sent invalid URL: jo
2024-07-22 15:38:30,948 - telegram.ext.Application - ERROR - No error handlers are registered, logging exception.
Traceback (most recent call last):
  File "/Users/airhao3/miniconda3/envs/bot/lib/python3.10/site-packages/httpx/_transports/default.py", line 69, in map_httpcore_exceptions
    yield
  File "/Users/airhao3/miniconda3/envs/bot/lib/python3.10/site-packages/httpx/_transports/default.py", line 373, in handle_async_request
    resp = await self._pool.handle_async_request(req)
  File "/Users/airhao3/miniconda3/envs/bot/lib/python3.10/site-packages/httpcore/_async/connection_pool.py", line 216, in handle_async_request
    raise exc from None
  File "/Users/airhao3/miniconda3/envs/bot/lib/python3.10/site-packages/httpcore/_async/connection_pool.py", line 196, in handle_async_request
    response = await connection.handle_async_request(
  File "/Users/airhao3/miniconda3/envs/bot/lib/python3.10/site-packages/httpcore/_async/socks_proxy.py", line 296, in handle_async_request
    raise exc
  File "/Users/airhao3/miniconda3/envs/bot/lib/python3.10/site-packages/httpcore/_async/socks_proxy.py", line 267, in handle_async_request
    stream = await stream.start_tls(**kwargs)
  File "/Users/airhao3/miniconda3/envs/bot/lib/python3.10/site-packages/httpcore/_backends/anyio.py", line 68, in start_tls
    with map_exceptions(exc_map):
  File "/Users/airhao3/miniconda3/envs/bot/lib/python3.10/contextlib.py", line 153, in __exit__
    self.gen.throw(typ, value, traceback)
  File "/Users/airhao3/miniconda3/envs/bot/lib/python3.10/site-packages/httpcore/_exceptions.py", line 14, in map_exceptions
    raise to_exc(exc) from exc
httpcore.ConnectTimeout

The above exception was the direct cause of the following exception:

Traceback (most recent call last):
  File "/Users/airhao3/miniconda3/envs/bot/lib/python3.10/site-packages/telegram/request/_httpxrequest.py", line 276, in do_request
    res = await self._client.request(
  File "/Users/airhao3/miniconda3/envs/bot/lib/python3.10/site-packages/httpx/_client.py", line 1574, in request
    return await self.send(request, auth=auth, follow_redirects=follow_redirects)
  File "/Users/airhao3/miniconda3/envs/bot/lib/python3.10/site-packages/httpx/_client.py", line 1661, in send
    response = await self._send_handling_auth(
  File "/Users/airhao3/miniconda3/envs/bot/lib/python3.10/site-packages/httpx/_client.py", line 1689, in _send_handling_auth
    response = await self._send_handling_redirects(
  File "/Users/airhao3/miniconda3/envs/bot/lib/python3.10/site-packages/httpx/_client.py", line 1726, in _send_handling_redirects
    response = await self._send_single_request(request)
  File "/Users/airhao3/miniconda3/envs/bot/lib/python3.10/site-packages/httpx/_client.py", line 1763, in _send_single_request
    response = await transport.handle_async_request(request)
  File "/Users/airhao3/miniconda3/envs/bot/lib/python3.10/site-packages/httpx/_transports/default.py", line 372, in handle_async_request
    with map_httpcore_exceptions():
  File "/Users/airhao3/miniconda3/envs/bot/lib/python3.10/contextlib.py", line 153, in __exit__
    self.gen.throw(typ, value, traceback)
  File "/Users/airhao3/miniconda3/envs/bot/lib/python3.10/site-packages/httpx/_transports/default.py", line 86, in map_httpcore_exceptions
    raise mapped_exc(message) from exc
httpx.ConnectTimeout

The above exception was the direct cause of the following exception:

Traceback (most recent call last):
  File "/Users/airhao3/miniconda3/envs/bot/lib/python3.10/site-packages/telegram/ext/_application.py", line 1335, in process_update
    await coroutine
  File "/Users/airhao3/miniconda3/envs/bot/lib/python3.10/site-packages/telegram/ext/_handlers/basehandler.py", line 157, in handle_update
    return await self.callback(update, context)
  File "/Users/airhao3/nextcloud/document/telegram-bot-python/telegram-bot-download-proxy.py", line 130, in download_video
    await update.message.reply_text("This is not a valid URL. Please send a video URL.")
  File "/Users/airhao3/miniconda3/envs/bot/lib/python3.10/site-packages/telegram/_message.py", line 1763, in reply_text
    return await self.get_bot().send_message(
  File "/Users/airhao3/miniconda3/envs/bot/lib/python3.10/site-packages/telegram/ext/_extbot.py", line 2907, in send_message
    return await super().send_message(
  File "/Users/airhao3/miniconda3/envs/bot/lib/python3.10/site-packages/telegram/_bot.py", line 1028, in send_message
    return await self._send_message(
  File "/Users/airhao3/miniconda3/envs/bot/lib/python3.10/site-packages/telegram/ext/_extbot.py", line 610, in _send_message
    result = await super()._send_message(
  File "/Users/airhao3/miniconda3/envs/bot/lib/python3.10/site-packages/telegram/_bot.py", line 744, in _send_message
    result = await self._post(
  File "/Users/airhao3/miniconda3/envs/bot/lib/python3.10/site-packages/telegram/_bot.py", line 622, in _post
    return await self._do_post(
  File "/Users/airhao3/miniconda3/envs/bot/lib/python3.10/site-packages/telegram/ext/_extbot.py", line 355, in _do_post
    return await super()._do_post(
  File "/Users/airhao3/miniconda3/envs/bot/lib/python3.10/site-packages/telegram/_bot.py", line 651, in _do_post
    result = await request.post(
  File "/Users/airhao3/miniconda3/envs/bot/lib/python3.10/site-packages/telegram/request/_baserequest.py", line 200, in post
    result = await self._request_wrapper(
  File "/Users/airhao3/miniconda3/envs/bot/lib/python3.10/site-packages/telegram/request/_baserequest.py", line 342, in _request_wrapper
    raise exc
  File "/Users/airhao3/miniconda3/envs/bot/lib/python3.10/site-packages/telegram/request/_baserequest.py", line 332, in _request_wrapper
    code, payload = await self.do_request(
  File "/Users/airhao3/miniconda3/envs/bot/lib/python3.10/site-packages/telegram/request/_httpxrequest.py", line 293, in do_request
    raise TimedOut from err
telegram.error.TimedOut: Timed out
2024-07-22 15:38:36,194 - httpx - INFO - HTTP Request: POST https://api.telegram.org/bot7064977852:AAGEEutTl0D6gVt-Jgz4aXJ4mxK8mLPdL_E/getUpdates "HTTP/1.1 200 OK"
2024-07-22 15:38:46,448 - httpx - INFO - HTTP Request: POST https://api.telegram.org/bot7064977852:AAGEEutTl0D6gVt-Jgz4aXJ4mxK8mLPdL_E/getUpdates "HTTP/1.1 200 OK"
2024-07-22 15:38:56,694 - httpx - INFO - HTTP Request: POST https://api.telegram.org/bot7064977852:AAGEEutTl0D6gVt-Jgz4aXJ4mxK8mLPdL_E/getUpdates "HTTP/1.1 200 OK"
2024-07-22 15:39:06,957 - httpx - INFO - HTTP Request: POST https://api.telegram.org/bot7064977852:AAGEEutTl0D6gVt-Jgz4aXJ4mxK8mLPdL_E/getUpdates "HTTP/1.1 200 OK"
